Workbook

Sheet Pack
B1: PACK | Q1: Parametros ajustables
B2: Bajada 32x47 | C2: 350g | E2: 300g | G2: 200g | I2: 150g | K2: 90g | M2: autoadhesivo | P2: Precio del papel por hoja
C3: 4/0 | D3: 4/4 | E3: 4/0 | F3: 4/4 | G3: 4/0 | H3: 4/4 | I3: 4/0 | J3: 4/4 | K3: 4/0 | L3: 4/4 | M3: 4/0 | O3: precio de papel | P3: XL | Q3: 33X48 | R3: 32X47 | S3: A4
B4: 100 a 300 | C4: =P37+$R$4 -> 10.346 | D4: =P37+$W$38*T37+$R$4 -> 18.046 | E4: =P37+$R$5 -> 9.5988 | F4: =P37+$W$38*T37+$R$5 -> 17.2988 | G4: =P37+$R$6 -> 9.0785 | H4: =P37+T37*$W$38+$R$6 -> 16.7785 | I4: =P37+$R$7 -> 8.7639 | J4: =P37+T37*$W$38+$R$7 -> 16.4639 | K4: =P37+$R$8 -> 8.4977 | L4: =P37+T37*$W$38+$R$8 -> 16.1977 | M4: =P37+$R$9 -> 10.6515 | O4: 350g | P4: =P24*P14 -> 3.64 | Q4: =Q24*Q14 -> 2.73 | R4: =R24*R14 -> 2.296 | S4: =S24*S14 -> 1.498
B5: 301 a 500 | C5: =P38+$R$4 -> 9.996 | D5: =P38+$W$38*T38+$R$4 -> 17.346 | E5: =P38+$R$5 -> 9.2488 | F5: =P38+$W$38*T38+$R$5 -> 16.5988 | G5: =P38+$R$6 -> 8.7285 | H5: =P38+T38*$W$38+$R$6 -> 16.0785 | I5: =P38+$R$7 -> 8.4139 | J5: =P38+T38*$W$38+$R$7 -> 15.7639 | K5: =P38+$R$8 -> 8.1477 | L5: =P38+T38*$W$38+$R$8 -> 15.4977 | M5: =P38+$R$9 -> 10.3015 | O5: 300g | P5: =P25*P15 -> 2.44904 | Q5: =Q25*Q15 -> 1.83678 | R5: =R25*R15 -> 1.5488 | S5: =S25*S15 -> 1.0769
B6: 501 a 1000 | C6: =P39+$R$4 -> 9.646 | D6: =P39+$W$38*T39+$R$4 -> 16.996 | E6: =P39+$R$5 -> 8.8988 | F6: =P39+$W$38*T39+$R$5 -> 16.2488 | G6: =P39+$R$6 -> 8.3785 | H6: =P39+T39*$W$38+$R$6 -> 15.7285 | I6: =P39+$R$7 -> 8.0639 | J6: =P39+T39*$W$38+$R$7 -> 15.4139 | K6: =P39+$R$8 -> 7.7977 | L6: =P39+T39*$W$38+$R$8 -> 15.1477 | M6: =P39+$R$9 -> 9.9515 | O6: 200g | P6: =P26*P16 -> 1.63229 | Q6: =Q26*Q16 -> 1.22452 | R6: =R26*R16 -> 1.0285 | S6: =S26*S16 -> 0.8228
O7: 150g | P7: =P27*P17 -> 1.089 | Q7: =Q27*Q17 -> 0.81675 | R7: =R27*R17 -> 0.7139 | S7: =S27*S17 -> 0.6534
B8: Bajada 33x48 | C8: 350g | E8: 300g | G8: 200g | I8: 150g | K8: 90g | M8: autoadhesivo | O8: 90g | P8: =P28*P18 -> 0 | Q8: =Q28*Q18 -> 0.5324 | R8: =R28*R18 -> 0.4477 | S8: =S28*S18 -> 0.5324
C9: 4/0 | D9: 4/4 | E9: 4/0 | F9: 4/4 | G9: 4/0 | H9: 4/4 | I9: 4/0 | J9: 4/4 | K9: 4/0 | L9: 4/4 | M9: 4/0 | O9: autoadhesivo | P9: =P29*P19 -> 5.203 | Q9: =Q29*Q19 -> 5.203 | R9: =R29*R19 -> 2.6015 | S9: =S29*S19 -> 1.6093
B10: 100 a 300 | C10: =P37+$Q$4 -> 10.78 | D10: =P37+T37*$W$38+$Q$4 -> 18.48 | E10: =P37+$Q$5 -> 9.88678 | F10: =P37+T37*$W$38+$Q$5 -> 17.58678 | G10: =P37+$Q$6 -> 9.27452 | H10: =P37+T37*$W$38+$Q$6 -> 16.97452 | I10: =P37+$Q$7 -> 8.86675 | J10: =P37+T37*$W$38+$Q$7 -> 16.56675 | K10: =P37+$Q$8 -> 8.5824 | L10: =P37+T37*$W$38+$Q$8 -> 16.2824 | M10: =P37+$Q$9 -> 13.253 | O10: cartulina triplex 300g | P10: =P30*P20 -> 0 | Q10: =Q30*Q20 -> 0 | R10: =R30*R20 -> 0 | S10: =S30*S20 -> 0
B11: 301 a 500 | C11: =P38+$Q$4 -> 10.43 | D11: =P38+T38*$W$38+$Q$4 -> 17.78 | E11: =P38+$Q$5 -> 9.53678 | F11: =P38+T38*$W$38+$Q$5 -> 16.88678 | G11: =P38+$Q$6 -> 8.92452 | H11: =P38+T38*$W$38+$Q$6 -> 16.27452 | I11: =P38+$Q$7 -> 8.51675 | J11: =P38+T38*$W$38+$Q$7 -> 15.86675 | K11: =P38+$Q$8 -> 8.2324 | L11: =P38+T38*$W$38+$Q$8 -> 15.5824 | M11: =P38+$Q$9 -> 12.903
B12: 501 a 1000 | C12: =P39+$Q$4 -> 10.08 | D12: =P39+T39*$W$38+$Q$4 -> 17.43 | E12: =P39+$Q$5 -> 9.18678 | F12: =P39+T39*$W$38+$Q$5 -> 16.53678 | G12: =P39+$Q$6 -> 8.57452 | H12: =P39+T39*$W$38+$Q$6 -> 15.92452 | I12: =P39+$Q$7 -> 8.16675 | J12: =P39+T39*$W$38+$Q$7 -> 15.51675 | K12: =P39+$Q$8 -> 7.8824 | L12: =P39+T39*$W$38+$Q$8 -> 15.2324 | M12: =P39+$Q$9 -> 12.553 | O12: Coeficiente papel
P13: XL | Q13: 33X48 | R13: 32X47 | S13: A4
B14: Bajada XL | C14: 350gr | E14: 300gr | G14: 200gr | I14: 150gr | K14: 90gr | M14: autoadhesivo | O14: 350g | P14: 1.4 | Q14: 1.4 | R14: 1.4 | S14: 1.4 | U14: COSTO DE BAJADA | V14: (costo de papel x coef ganacia) + (costo clic * coef 4/0) + (costo clic x coef 4/4)
C15: 4/0 | D15: 4/4 | E15: 4/0 | F15: 4/4 | G15: 4/0 | H15: 4/4 | I15: 4/0 | J15: 4/4 | K15: 4/0 | L15: 4/4 | M15: 4/0 | O15: 300g | P15: 1.21 | Q15: 1.21 | R15: 1.21 | S15: 1.21 | U15: COSTO DE PAPEL | V15: costo de pliego/coef de corte
B16: 100 a 300 | C16: =Q37+$P$4 -> 23.765 | D16: =Q37+T37*$W$38+$P$4 -> 31.465 | E16: =Q37+$P$5 -> 22.57404 | F16: =Q37+T37*$W$38+$P$5 -> 30.27404 | G16: =Q37+$P$6 -> 21.75729 | H16: =Q37+T37*$W$38+$P$6 -> 29.45729 | I16: =Q37+$P$7 -> 21.214 | J16: =Q37+T37*$W$38+$P$7 -> 28.914 | K16: =Q37+$P$8 -> 20.125 | L16: =Q37+T37*$W$38+$P$8 -> 27.825 | M16: =Q37+$P$9 -> 25.328 | O16: 200g | P16: 1.21 | Q16: 1.21 | R16: 1.21 | S16: 1.21 | U16: costo de clic | V16: toner + gastos amortiz
B17: 301 a 500 | C17: =Q38+$P$4 -> 22.89 | D17: =Q38+T38*$W$38+$P$4 -> 30.24 | E17: =Q38+$P$5 -> 21.69904 | F17: =Q38+T38*$W$38+$P$5 -> 29.04904 | G17: =Q38+$P$6 -> 20.88229 | H17: =Q38+T38*$W$38+$P$6 -> 28.23229 | I17: =Q38+$P$7 -> 20.339 | J17: =Q38+T38*$W$38+$P$7 -> 27.689 | K17: =Q38+$P$8 -> 19.25 | L17: =Q38+T38*$W$38+$P$8 -> 26.6 | M17: =Q38+$P$9 -> 24.453 | O17: 150g | P17: 1.21 | Q17: 1.21 | R17: 1.21 | S17: 1.21
B18: 501 a 1000 | C18: =Q39+$P$4 -> 22.015 | D18: =Q39+T39*$W$38+$P$4 -> 29.365 | E18: =Q39+$P$5 -> 20.82404 | F18: =Q39+T39*$W$38+$P$5 -> 28.17404 | G18: =Q39+$P$6 -> 20.00729 | H18: =Q39+T39*$W$38+$P$6 -> 27.35729 | I18: =Q39+$P$7 -> 19.464 | J18: =Q39+T39*$W$38+$P$7 -> 26.814 | K18: =Q39+$P$8 -> 18.375 | L18: =Q39+T39*$W$38+$P$8 -> 25.725 | M18: =Q39+$P$9 -> 23.578 | O18: 90g | Q18: 1.21 | R18: 1.21 | S18: 1.21
O19: autoadhesivo | P19: 1.21 | Q19: 1.21 | R19: 1.21 | S19: 1.21
B20: Bajada A4 | C20: 350gr | E20: 300gr | G20: 200gr | I20: 150gr | K20: 90gr | M20: autoadhesivo
C21: 4/0 | D21: 4/4 | E21: 4/0 | F21: 4/4 | G21: 4/0 | H21: 4/4 | I21: 4/0 | J21: 4/4 | K21: 4/0 | L21: 4/4 | M21: 4/0
B22: 100 a 300 | C22: =R37+$S$4 -> 5.523 | D22: =R37+T37*$W$38+$S$4 -> 13.223 | E22: =R37+$S$5 -> 5.1019 | F22: =R37+T37*$W$38+$S$5 -> 12.8019 | G22: =R37+$S$6 -> 4.8478 | H22: =R37+T37*$W$38+$S$6 -> 12.5478 | I22: =R37+$S$7 -> 4.6784 | J22: =R37+T37*$W$38+$S$7 -> 12.3784 | K22: =R37+$S$8 -> 4.5574 | L22: =R37+T37*$W$38+$S$8 -> 12.2574 | M22: =R37+$S$9 -> 5.6343 | O22: costo de papel
B23: 301 a 500 | C23: =R38+$S$4 -> 5.348 | D23: =R38+T38*$W$38+$S$4 -> 12.698 | E23: =R38+$S$5 -> 4.9269 | F23: =R38+T38*$W$38+$S$5 -> 12.2769 | G23: =R38+$S$6 -> 4.6728 | H23: =R38+T38*$W$38+$S$6 -> 12.0228 | I23: =R38+$S$7 -> 4.5034 | J23: =R38+T38*$W$38+$S$7 -> 11.8534 | K23: =R38+$S$8 -> 4.3824 | L23: =R38+T38*$W$38+$S$8 -> 11.7324 | M23: =R38+$S$9 -> 5.4593 | P23: XL | Q23: 33X48 | R23: 32X47 | S23: A4
B24: 501 a 1000 | C24: =R39+$S$4 -> 5.173 | D24: =R39+T39*$W$38+$S$4 -> 12.523 | E24: =R39+$S$5 -> 4.7519 | F24: =R39+T39*$W$38+$S$5 -> 12.1019 | G24: =R39+$S$6 -> 4.4978 | H24: =R39+T39*$W$38+$S$6 -> 11.8478 | I24: =R39+$S$7 -> 4.3284 | J24: =R39+T39*$W$38+$S$7 -> 11.6784 | K24: =R39+$S$8 -> 4.2074 | L24: =R39+T39*$W$38+$S$8 -> 11.5574 | M24: =R39+$S$9 -> 5.2843 | O24: 350g | P24: 2.6 | Q24: 1.95 | R24: 1.64 | S24: 1.07
O25: 300g | P25: 2.024 | Q25: 1.518 | R25: 1.28 | S25: 0.89 | U25: 3000
O26: 200g | P26: 1.349 | Q26: 1.012 | R26: 0.85 | S26: 0.68 | U26: 1000
O27: 150g | P27: 0.9 | Q27: 0.675 | R27: 0.59 | S27: 0.54 | U27: 200
B28: BLANCO Y NEGRO | O28: 90g | P28: 0.587 | Q28: 0.44 | R28: 0.37 | S28: 0.44 | U28: 5000
B29: 32x47 | C29: 350gr | E29: 300gr | G29: 200gr | I29: 150gr | K29: 90gr | M29: autoadhesivo | O29: autoadhesivo | P29: 4.3 | Q29: 4.3 | R29: 2.15 | S29: 1.33 | U29: 2200
B30: Bajada ByN | C30: 1/0 | D30: 1/1 | E30: 1/0 | F30: 1/1 | G30: 1/0 | H30: 1/1 | I30: 1/0 | J30: 1/1 | K30: 1/0 | L30: 1/1 | M30: 1/0 | U30: 6900
B31: 101 a 500 | C31: =P43+$R$4 -> 4.796 | D31: =P43+$W$39*T43+$R$4 -> 5.996 | E31: =P43+$R$5 -> 4.0488 | F31: =P43+$W$39*T43+$R$5 -> 5.2488 | G31: =P43+$R$6 -> 3.5285 | H31: =P43+T43*$W$39+$R$6 -> 4.7285 | I31: =P43+$R$7 -> 3.2139 | J31: =P43+T43*$W$39+$R$7 -> 4.4139 | K31: =P43+$R$8 -> 2.9477 | L31: =P43+T43*$W$39+$R$8 -> 4.1477 | M31: =P43+$R$9 -> 5.1015 | U31: 300
B32: 501 a 1000 | C32: =P44+$R$4 -> 4.596 | D32: =P44+$W$39*T44+$R$4 -> 5.696 | E32: =P44+$R$5 -> 3.8488 | F32: =P44+$W$39*T44+$R$5 -> 4.9488 | G32: =P44+$R$6 -> 3.3285 | H32: =P44+T44*$W$39+$R$6 -> 4.4285 | I32: =P44+$R$7 -> 3.0139 | J32: =P44+T44*$W$39+$R$7 -> 4.1139 | K32: =P44+$R$8 -> 2.7477 | L32: =P44+T44*$W$39+$R$8 -> 3.8477 | M32: =P44+$R$9 -> 4.9015 | U32: 200
B33: 1001 a 5000 | C33: =P45+$R$4 -> 4.496 | D33: =P45+$W$39*T45+$R$4 -> 5.596 | E33: =P45+$R$5 -> 3.7488 | F33: =P45+$W$39*T45+$R$5 -> 4.8488 | G33: =P45+$R$6 -> 3.2285 | H33: =P45+T45*$W$39+$R$6 -> 4.3285 | I33: =P45+$R$7 -> 2.9139 | J33: =P45+T45*$W$39+$R$7 -> 4.0139 | K33: =P45+$R$8 -> 2.6477 | L33: =P45+T45*$W$39+$R$8 -> 3.7477 | M33: =P45+$R$9 -> 4.8015 | P33: precio x clic | U33: =SUM(U25:U32) -> 18800
O34: Rango Pack color | P34: A3 | Q34: XL | R34: A4 | S34: Coef 4/0 | T34: coef 4/4
B35: 33x48 | C35: 350gr | E35: 300gr | G35: 200gr | I35: 150gr | K35: 90gr | M35: autoadhesivo | O35: 1 a 20 | P35: =S35*$W$38 -> 10.5 | Q35: =P35*$W$36 -> 26.25 | R35: =P35*$W$37 -> 5.25 | S35: 1.5 | T35: 1.2
B36: Bajada ByN | C36: 1/0 | D36: 1/1 | E36: 1/0 | F36: 1/1 | G36: 1/0 | H36: 1/1 | I36: 1/0 | J36: 1/1 | K36: 1/0 | L36: 1/1 | M36: 1/0 | O36: 20 a 100 | P36: =S36*$W$38 -> 9.1 | Q36: =P36*$W$36 -> 22.75 | R36: =P36*$W$37 -> 4.55 | S36: 1.3 | T36: 1.2 | V36: Coeficiente XL | W36: 2.5
B37: 101 a 500 | C37: =P43+$Q$4 -> 5.23 | D37: =P43+$W$39*T43+$Q$4 -> 6.43 | E37: =P43+$Q$5 -> 4.33678 | F37: =P43+$W$39*T43+$Q$5 -> 5.53678 | G37: =P43+$Q$6 -> 3.72452 | H37: =P43+$W$39*T43+$Q$6 -> 4.92452 | I37: =P43+$Q$7 -> 3.31675 | J37: =P43+$W$39*T43+$Q$7 -> 4.51675 | K37: =P43+$Q$8 -> 3.0324 | L37: =P43+$W$39*T43+$Q$8 -> 4.2324 | M37: =P43+$Q$9 -> 7.703 | O37: 100 a 300 | P37: =S37*$W$38 -> 8.05 | Q37: =P37*$W$36 -> 20.125 | R37: =P37*$W$37 -> 4.025 | S37: 1.15 | T37: 1.1 | V37: Coeficiente A4 | W37: 0.5
B38: 501 a 1000 | C38: =P44+$Q$4 -> 5.03 | D38: =P44+$W$39*T44+$Q$4 -> 6.13 | E38: =P44+$Q$5 -> 4.13678 | F38: =P44+$W$39*T44+$Q$5 -> 5.23678 | G38: =P44+$Q$6 -> 3.52452 | H38: =P44+$W$39*T44+$Q$6 -> 4.62452 | I38: =P44+$Q$7 -> 3.11675 | J38: =P44+$W$39*T44+$Q$7 -> 4.21675 | K38: =P44+$Q$8 -> 2.8324 | L38: =P44+$W$39*T44+$Q$8 -> 3.9324 | M38: =P44+$Q$9 -> 7.503 | O38: 301 a 500 | P38: =S38*$W$38 -> 7.7 | Q38: =P38*$W$36 -> 19.25 | R38: =P38*$W$37 -> 3.85 | S38: 1.1 | T38: 1.05 | V38: costo clic color | W38: 7
B39: 1001 a 5000 | C39: =P45+$Q$4 -> 4.93 | D39: =P45+$W$39*T45+$Q$4 -> 6.03 | E39: =P45+$Q$5 -> 4.03678 | F39: =P45+$W$39*T45+$Q$5 -> 5.13678 | G39: =P45+$Q$6 -> 3.42452 | H39: =P45+$W$39*T45+$Q$6 -> 4.52452 | I39: =P45+$Q$7 -> 3.01675 | J39: =P45+$W$39*T45+$Q$7 -> 4.11675 | K39: =P45+$Q$8 -> 2.7324 | L39: =P45+$W$39*T45+$Q$8 -> 3.8324 | M39: =P45+$Q$9 -> 7.403 | O39: 501 a 1000 | P39: =S39*$W$38 -> 7.35 | Q39: =P39*$W$36 -> 18.375 | R39: =P39*$W$37 -> 3.675 | S39: 1.05 | T39: 1.05 | V39: costo clic ByN | W39: 1
O40: 502 a 1000 | P40: =S40*$W$38 -> 7 | Q40: =P40*$W$36 -> 17.5 | R40: =P40*$W$37 -> 3.5 | S40: 1 | T40: 1.05
...

Sheet Laminado
A1: =A3/C1*B1 -> 320366.86 | B1: 1.21 | C1: 1 | I1: ,
A2: =A3*B1 -> 320366.86 | B2: Laminado x lado | C2: 1.2 | D2: 1.16 | G2: 1.1 | I2: 1.2
A3: 264766 | B3: Tamaño de hoja A3Plus (32x47cm) | K3: NUEVA TERMINACION
A4: 1 | B4: 300000 | C4: 33 | E4: =B4/C4 -> 9090.9091 | F4: 52x72 | H4: 72x102
A5: costo | B5: =A3/A4 -> 264766 | C5: =A2/B4*C4*C1 -> 35.240355
A6: frente | B6: Cantidad | C6: brillo | D6: mate | E6: Laca UV | F6: Brillo | G6: Mate | H6: Brillo | I6: mate | J6: Laca UV | K6: Soft Touch | N6: =C6 -> brillo | O6: =D6 -> mate | P6: =E6 -> Laca UV | Q6: =F6 -> Brillo | R6: =G6 -> Mate
B7: 0 - 10 | C7: =C5*L7*D2 -> 163.51525 | D7: =C7*D2 -> 189.67768 | E7: =C7/I2 -> 136.2627 | F7: =C7 -> 163.51525 | G7: =D7 -> 189.67768 | J7: =E7 -> 136.2627 | K7: 8.6 | L7: 4 | N7: =C7*1.9 -> 310.67897 | O7: =D7*1.9 -> 360.3876 | P7: =E7*1.9 -> 258.89914 | Q7: =F7*1.9 -> 310.67897 | R7: =G7*1.9 -> 360.3876
B8: 11-50 | C8: =C5*L8*D2 -> 151.2516 | D8: =C8*D2 -> 175.45186 | E8: =C8/I2 -> 126.043 | F8: =C8 -> 151.2516 | G8: =D8 -> 175.45186 | J8: =E8 -> 126.043 | K8: 6.6 | L8: 3.7 | N8: =C8*1.9 -> 287.37804 | O8: =D8*1.9 -> 333.35853 | P8: =E8*1.9 -> 239.4817 | Q8: =F8*1.9 -> 287.37804 | R8: =G8*1.9 -> 333.35853
B9: 51-100 | C9: =C5*L9*D2 -> 138.98796 | D9: =C9*D2 -> 161.22603 | E9: =C9/I2 -> 115.8233 | F9: =C9 -> 138.98796 | G9: =D9 -> 161.22603 | J9: =E9 -> 115.8233 | K9: 6 | L9: 3.4 | N9: =C9*1.9 -> 264.07712 | O9: =D9*1.9 -> 306.32946 | P9: =E9*1.9 -> 220.06427 | Q9: =F9*1.9 -> 264.07712 | R9: =G9*1.9 -> 306.32946
B10: 101-500 | C10: =C5*L10*D2 -> 126.72432 | D10: =C10*D2 -> 147.00021 | E10: =C10/I2 -> 105.6036 | F10: =C10 -> 126.72432 | G10: =D10 -> 147.00021 | J10: =E10 -> 105.6036 | K10: 5.7 | L10: 3.1 | N10: =C10*1.9 -> 240.7762 | O10: =D10*1.9 -> 279.30039 | P10: =E10*1.9 -> 200.64683 | Q10: =F10*1.9 -> 240.7762 | R10: =G10*1.9 -> 279.30039
B11: 501-1000 | C11: =C5*L11*D2 -> 118.54855 | D11: =C11*D2 -> 137.51632 | E11: =C11/I2 -> 98.790461 | F11: =C11 -> 118.54855 | G11: =D11 -> 137.51632 | J11: =E11 -> 98.790461 | K11: 5.2 | L11: 2.9 | N11: =C11*1.9 -> 225.24225 | O11: =D11*1.9 -> 261.28101 | P11: =E11*1.9 -> 187.70188 | Q11: =F11*1.9 -> 225.24225 | R11: =G11*1.9 -> 261.28101
B12: 1001 + | C12: =C5*L12*D2 -> 110.37279 | D12: =C12*D2 -> 128.03244 | E12: =C12/I2 -> 91.977326 | F12: =C12 -> 110.37279 | G12: =D12 -> 128.03244 | J12: 4 | K12: aterciopelado | L12: 2.7 | N12: =C12*1.9 -> 209.7083 | O12: =D12*1.9 -> 243.26163 | P12: =E12*1.9 -> 174.75692 | Q12: =F12*1.9 -> 209.7083 | R12: =G12*1.9 -> 243.26163
B13: 1001 + | C13: =C5*L13*D2 -> 102.19703 | D13: =C13*D2 -> 118.54855 | E13: =C13/I2 -> 85.16419 | F13: =C13 -> 102.19703 | G13: =D13 -> 118.54855 | J13: 4 | K13: aterciopelado | L13: 2.5 | N13: =C13*1.9 -> 194.17435 | O13: =D13*1.9 -> 225.24225 | P13: =E13*1.9 -> 161.81196 | Q13: =F13*1.9 -> 194.17435 | R13: =G13*1.9 -> 225.24225
B16: Plastificado x unid | C16: A4 | D16: Oficio | G16: A3
B17: precio | C17: 15 | D17: 21 | G17: 25
B19: Adicional Trabajo EXPRESS | D19: + 40%
A23: 45415 | B23: uss | C23: 901 | N23: 25.74 | O23: 24.024 | P23: 24.024
A24: medida | N24: 24.024 | O24: 20.592 | P24: 20.592
A25: PROBOP | B25: bobina | C25: cm | D25: costo | E25: IVA | F25: $ cm lineal | G25: hoja A3+ 33x48 | N25: 20.592 | O25: 18.876 | P25: 18.876
A26: mate | B26: 52 cm | C26: 300000 | D26: 264766 | E26: =D26*1.21 -> 320366.86 | F26: =E26/C26 -> 1.0678895 | G26: =F26*33 -> 35.240355 | N26: 18.876 | O26: 17.16 | P26: 17.16
N27: 17.16 | O27: 15.444 | P27: 15.444
A28: LACA UV | B28: US x kilo | C28: 44 | D28: 4000 | N28: 15.444 | O28: 13.728 | P28: 13.728
A29: 4 | B29: =C28*A29 -> 176 | C29: =B29*C23 -> 158576 | D29: =C29/D28 -> 39.644

Sheet corte
A3: corte | N3: Ejemplo: | R3: Ejemplo:
N4: CUANTO SALE CORTAR 100 bajadas para postales 10x15cm de 300g | R4: CUANTO SALE CORTAR 500 bajadas para tarjetas 9x5cm de 350g (corte seco)
N6: DATOS: | R6: DATOS:
A7: CORTE | N7: Cantidad | O7: 100 bajadas | R7: Cantidad | S7: 500 bajadas
A8: Medidas | B8: Posturas x pliego | C8: Cortes | E8: 1 cm equivale, aproximadamente y a modo de referencia, a las siguientes cantidades de papel sin laminar. | N8: Papel | O8: 300g | R8: Papel | S8: 350g
A9: Al medio | B9: 2 | C9: 1 | N9: Cortes | O9: 8 cortes | R9: Cortes | S9: 13 cortes
A10: A3 - refilado | B10: 1 | C10: 4 | F10: Gramos | G10: Unid
A11: A4 | B11: 2 | C11: 5 | F11: 350 g | G11: 35 | N11: Ciclo de corte: 100/46= 2,17cm = $60 | R11: Ciclo de corte: 500/35= 14,28cm = $70
A12: 15x21 | B12: 4 | C12: 6 | F12: 300 g | G12: 46 | N12: Cantidad de cortes: 8 cortes: $20 | R12: Cantidad de cortes: $40
A13: 10x15 | B13: 9 | C13: 8 | F13: 200 g | G13: 70 | N13: Precio total por corte: $20+$60=$80 | R13: Precio total por corte: $70+$40=$110
A14: 10x10 | B14: 12 | C14: 9 | F14: 150 g | G14: 81
A15: 9x5 corte seco | B15: 30 | C15: 13 | F15: 90 g | G15: 95
A16: 9x5 doble corte | B16: 24 | C16: 24 | F16: Autoadhesivo | G16: 60 | N16: Ejemplo:
A17: 7x5 | B17: 32 | C17: 45 | F17: Imantada | G17: 14 | N17: CUANTO SALE CORTAR 2000 bajadas para folletos 10x15cm de 90g
A18: 5x5 | B18: 40 | C18: 54
A19: 6x4 | B19: 55 | C19: 73 | N19: DATOS:
N20: Cantidad | O20: 2000 bajadas
N21: Papel | O21: 90g
N22: Cortes | O22: 8 cortes
A23: Ciclo de corte hasta 33X70 cm | E23: Cantidad de cortes
A24: hasta 2 cm | B24: 70 | E24: Cantidad de cortes | F24: $ | N24: Ciclo de corte: 2000/95= 21,05 cm = $90 + (5cm extras x $15) = $165
A25: hasta 6 cm | B25: 90 | C25: 1275+60+200 | E25: 1 a 5 cortes | F25: 0 | N25: Cantidad de cortes: $20
A26: hasta 10 cm | B26: 120 | E26: 6 a 10 cortes | F26: 40 | N26: Precio total por corte: $165+$20 =$185
A27: hasta 16 cm | B27: 150 | E27: 11 a 15 cortes | F27: 60
A28: Adicional por cada cm extra $10 | E28: 16 a 20 cortes | F28: 80 | N28: FORMULA: CICLO DE CORTE + CANTIDAD DE CORTES = PRECIO POR CORTE
E29: 21 a 40 cortes | F29: 100
E30: 40 a 80 cortes | F30: 150
A31: Adicional por corte EXPRESS: 40%
A32: (en el momento)

Sheet circulares
O4: COSTO DÓLAR
D5: troq circularf frente | O5: 230
C7: 1CM | D7: 2CM | E7: 3CM | F7: 4CM | G7: 5CM | H7: 6CM | I7: 7CM | J7: 8CM | K7: 9CM
B8: 100 | C8: =(P23+Y33)*C25 -> 227147.85 | D8: =(P23+Y33)*D25 -> 227147.85 | E8: =(P23+X33)*E25 -> 227031.04 | F8: =(P24+X33)*F25 -> 406389.03 | G8: =(P24+W34)*G25 -> 609158.77 | H8: =(P24+V34)*H25 -> 811916.72 | I8: =(P24+V34)*I25 -> 1014895.9 | J8: =(P24+U34)*J25 -> 1420424.1 | K8: =(P24+U34)*K25 -> 1826259.5 | O8: CLICK A3+ | P8: PAPEL
B9: 200 | C9: =(P23+Y33)*C26 -> 227147.85 | D9: =(P23+Y33)*D26 -> 227147.85 | E9: =(P24+X33)*E26 -> 406389.03 | F9: =(P24+X34)*F26 -> 609424.26 | G9: =(P24+W34)*G26 -> 1015264.6 | H9: =(P24+V34)*H26 -> 1623833.4 | I9: =(P24+V34)*I26 -> 1826812.6 | J9: =(P24+U35)*J26 -> 2840457.1 | K9: =(P24+U35)*K26 -> 3449126.4 | O9: 0.147 | P9: 0.21175
B10: 300 | C10: =(P23+Y33)*C27 -> 227147.85 | D10: =(P24+Y33)*D27 -> 406622.66 | E10: =(P24+X34)*E27 -> 609424.26 | F10: =(P24+X34)*F27 -> 1015707.1 | G10: =(P24+W34)*G27 -> 1624423.4 | H10: =(P24+V35)*H27 -> 2232402.2 | I10: =(P24+V35)*I27 -> 2638293.6 | J10: =(P24+U35)*J27 -> 4057795.8 | K10: =(P25+U35)*K27 -> 4923266.5
B11: 500 | C11: =(P23+Y33)*C28 -> 227147.85 | D11: =(P24+Y34)*D28 -> 406495.23 | E11: =(P24+X34)*E28 -> 812565.68 | F11: =(P24+X34)*F28 -> 1625131.4 | G11: =(P24+W35)*G28 -> 2639165.1 | H11: =(P24+V35)*H28 -> 3653021.9 | I11: =(P24+V35)*I28 -> 4261858.8 | J11: =(P25+U36)*J28 -> 6694779 | K11: =(P25+U36)*K28 -> 8270021.1
B12: 1000 | C12: =(P23+Y33)*C29 -> 227147.85 | D12: =(P24+Y34)*D29 -> 812990.45 | E12: =(P24+X34)*E29 -> 1625131.4 | F12: =(P24+X35)*F29 -> 3046397.2 | G12: =(P24+W35)*G29 -> 5075317.5 | H12: =(P25+V36)*H29 -> 7090418 | I12: =(P25+V36)*I29 -> 8272154.3 | J12: =(P26+U37)*J29 -> 12791844 | K12: =(P26+U37)*K29 -> 16037536
C14: troq circular frente y dorso
C15: 1CM | D15: 2CM | E15: 3CM | F15: 4CM | G15: 5CM | H15: 6CM | I15: 7CM | J15: 8CM | K15: 9CM
B16: 100 | C16: =C8*S23 -> 227408.01 | D16: =D8*S23 -> 227408.01 | E16: =E8*S23 -> 227291.06 | F16: =F8*S23 -> 406854.47 | G16: =G8*S23 -> 609856.44 | H16: =H8*S23 -> 812846.61 | I16: =I8*S23 -> 1016058.3 | J16: =J8*S23 -> 1422050.9 | K16: =K8*S23 -> 1828351.1
B17: 200 | C17: =C9*S24 -> 227408.01 | D17: =D9*S24 -> 227408.01 | E17: =E9*S24 -> 406854.47 | F17: =F9*S24 -> 610122.23 | G17: =G9*S24 -> 1016427.4 | H17: =H9*S24 -> 1625693.2 | I17: =I9*S24 -> 1828904.9 | J17: =J9*S24 -> 2843710.2 | K17: =K9*S24 -> 3453076.7
B18: 300 | C18: =C10*S25 -> 227408.01 | D18: =D10*S25 -> 407088.36 | E18: =E10*S25 -> 610122.23 | F18: =F10*S25 -> 1016870.4 | G18: =G10*S25 -> 1626283.9 | H18: =H10*S25 -> 2234959 | I18: =I10*S25 -> 2641315.2 | J18: =J10*S25 -> 4062443.2 | K18: =K10*S25 -> 4928905.1
B19: 500 | C19: =C11*S26 -> 227408.01 | D19: =D11*S26 -> 406960.78 | E19: =E11*S26 -> 813496.31 | F19: =F11*S26 -> 1626992.6 | G19: =G11*S26 -> 2642187.7 | H19: =H11*S26 -> 3657205.7 | I19: =I11*S26 -> 4266739.9 | J19: =J11*S26 -> 6702446.6 | K19: =K11*S26 -> 8279492.8
B20: 1000 | C20: =C12*S27 -> 227408.01 | D20: =D12*S27 -> 813921.57 | E20: =E12*S27 -> 1626992.6 | F20: =F12*S27 -> 3049886.3 | G20: =G12*S27 -> 5081130.3 | H20: =H12*S27 -> 7098538.6 | I20: =I12*S27 -> 8281628.4 | J20: =J12*S27 -> 12806495 | K20: =K12*S27 -> 16055904
O22: CLICK A3+ | P22: 4/0 | Q22: CLICK FYD | R22: x pliegos
N23: 1 | O23: 1 | P23: =Bajadas!E4 -> 226446.98 | Q23: =Bajadas!F4 -> 226706.33 | R23: =Bajadas!AH48 -> 1.9 | S23: =Q23/P23 -> 1.0011453
C24: 1CM | D24: 2CM | E24: 3CM | F24: 4CM | G24: 5CM | H24: 6CM | I24: 7CM | J24: 8CM | K24: 9CM | N24: 2 a 25 | O24: 1 | P24: =Bajadas!E5 -> 202610.45 | Q24: =Bajadas!F5 -> 202842.5 | R24: =Bajadas!AH49 -> 1.7 | S24: =Q24/P24 -> 1.0011453
B25: 100 | C25: 1 | D25: 1 | E25: 1 | F25: 2 | G25: 3 | H25: 4 | I25: 5 | J25: 7 | K25: 9 | N25: 26 a 50 | O25: 1 | P25: =Bajadas!E6 -> 196651.32 | Q25: =Bajadas!F6 -> 196876.55 | R25: =Bajadas!AH50 -> 1.65 | S25: =Q25/P25 -> 1.0011453
B26: 200 | C26: 1 | D26: 1 | E26: 2 | F26: 3 | G26: 5 | H26: 8 | I26: 9 | J26: 14 | K26: 17 | N26: 51 a 100 | O26: 1 | P26: =Bajadas!E7 -> 190692.19 | Q26: =Bajadas!F7 -> 190910.59 | R26: =Bajadas!AH51 -> 1.6 | S26: =Q26/P26 -> 1.0011453
B27: 300 | C27: 1 | D27: 2 | E27: 3 | F27: 5 | G27: 8 | H27: 11 | I27: 13 | J27: 20 | K27: 25 | N27: 101 a 300 | O27: 1 | P27: =Bajadas!E8 -> 184733.06 | Q27: =Bajadas!F8 -> 184944.63 | R27: =Bajadas!AH52 -> 1.55 | S27: =Q27/P27 -> 1.0011453
B28: 500 | C28: 1 | D28: 2 | E28: 4 | F28: 8 | G28: 13 | H28: 18 | I28: 21 | J28: 34 | K28: 42 | N28: 301 a 500 | O28: 1 | P28: =Bajadas!E9 -> 178773.93 | Q28: =Bajadas!F9 -> 178978.68 | R28: =Bajadas!AH53 -> 1.5 | S28: =Q28/P28 -> 1.0011453
B29: 1000 | C29: 1 | D29: 4 | E29: 8 | F29: 15 | G29: 25 | H29: 36 | I29: 42 | J29: 67 | K29: 84 | N29: 501 a 1000 | O29: 1 | P29: =Bajadas!E10 -> 172814.8 | Q29: =Bajadas!F10 -> 173012.72 | R29: =Bajadas!AH54 -> 1.45 | S29: =Q29/P29 -> 1.0011453
N30: 1000 | O30: 1 | P30: =Bajadas!E11 -> 166855.67 | Q30: =Bajadas!F11 -> 167046.77 | R30: =Bajadas!AH55 -> 1.4 | S30: =Q30/P30 -> 1.0011453
O32: Laminado x 1 | P32: Laminado x 2 | T32: =troquelados!W44 | U32: =troquelados!X44 -> SIMPLE | V32: =troquelados!Y44 -> MEDIO | W32: =troquelados!Z44 -> COMPLEJO | X32: =troquelados!AA44 -> MUY COMPLEJO | Y32: =troquelados!AB44 -> ULTRA COMPLEJO
N33: 1 a 10 | O33: =Laminado!C7 -> 163.51525 | P33: =O33*2 -> 327.03049 | T33: =troquelados!W45 -> 1 a 2 | U33: =troquelados!X45 -> 338 | V33: =troquelados!Y45 -> 405.6 | W33: =troquelados!Z45 -> 486.72 | X33: =troquelados!AA45 -> 584.064 | Y33: =troquelados!AB45 -> 700.8768
N34: 11 a 50 | O34: =Laminado!C8 -> 151.2516 | P34: =O34*2 -> 302.5032 | T34: =troquelados!W46 -> 3 a 9 | U34: =troquelados!X46 -> 307.27273 | V34: =troquelados!Y46 -> 368.72727 | W34: =troquelados!Z46 -> 442.47273 | X34: =troquelados!AA46 -> 530.96727 | Y34: =troquelados!AB46 -> 637.16073
N35: 51 a 100 | O35: =Laminado!C9 -> 138.98796 | P35: =O35*2 -> 277.97592 | T35: =troquelados!W47 -> 10 a 25 | U35: =troquelados!X47 -> 279.33884 | V35: =troquelados!Y47 -> 335.20661 | W35: =troquelados!Z47 -> 402.24793 | X35: =troquelados!AA47 -> 482.69752 | Y35: =troquelados!AB47 -> 579.23702
N36: 100 | O36: =Laminado!C10 -> 126.72432 | P36: =O36*2 -> 253.44863 | T36: =troquelados!W48 -> 26 a 50 | U36: =troquelados!X48 -> 253.9444 | V36: =troquelados!Y48 -> 304.73328 | W36: =troquelados!Z48 -> 365.67994 | X36: =troquelados!AA48 -> 438.81593 | Y36: =troquelados!AB48 -> 526.57911
O37: =Laminado!C11 -> 118.54855 | P37: =O37*2 -> 237.09711 | T37: =troquelados!W49 -> 51 a 100 | U37: =troquelados!X49 -> 230.85855 | V37: =troquelados!Y49 -> 277.03026 | W37: =troquelados!Z49 -> 332.43631 | X37: =troquelados!AA49 -> 398.92357 | Y37: =troquelados!AB49 -> 478.70828
P38: =O38*2 -> 0 | T38: =troquelados!W50 -> mas de 100 | U38: =troquelados!X50 -> 209.87141 | V38: =troquelados!Y50 -> 251.84569 | W38: =troquelados!Z50 -> 302.21483 | X38: =troquelados!AA50 -> 362.65779 | Y38: =troquelados!AB50 -> 435.18935

Sheet troquelados
R1: 1 | S1: 1.15 | T1: 1.3 | U1: 1.45 | V1: 1.6
R2: 15x15 cm. | S2: 7x7 cm. | T2: 4x4 cm. | U2: 2x2 cm. | V2: 1x1 cm,
C3: planchas troqueladas | R3: SIMPLE | S3: MEDIO | T3: COMPLEJO | U3: MUY COMPLEJO | V3: ULTRA COMPLEJO | X3: Dólar | Y3: 168
P4: 1.7 | Q4: 1 a 2 | R4: 118.8 | S4: 145.2 | T4: 171.6 | U4: 184.8 | V4: 211.2
A5: stickers | B5: 1CM | C5: 2CM | D5: 3CM | E5: 4CM | F5: 5CM | G5: 6CM | H5: 7CM | I5: 8CM | J5: 9CM | K5: 10cm | L5: 11cm. | M5: 12-13-14-15cm. | N5: 16/17 | O5: 18/19/20cm. | P5: 1.6 | Q5: 3 a 9 | R5: 99 | S5: 125.4 | T5: 151.8 | U5: 165 | V5: 191.4 | W5: 0.356 | X5: Coeficiente XL | Y5: =Y7*Z5 -> 73.92 | Z5: 2 | AB5: 100
A6: 100 | B6: =(Q20+AB20)*$B$42 -> 523932.14 | C6: =(Q20+AB20)*$C$42 -> 523932.14 | D6: =(Q20+AA20)*$D$42 -> 523842.28 | E6: =(Q21+Z20)*$E$42 -> 937346.8 | F6: =(Q21+Z21)*$F$42 -> 1405918.1 | G6: =(Q21+Z21)*$G$42 -> 1874557.5 | H6: =(Q21+Y21)*$H$42 -> 2342913.2 | I6: =(Q21+Y21)*$I$42 -> 3280078.5 | J6: =(Q21+Y21)*$J$42 -> 4217243.7 | K6: =(Q21+Y21)*$J$42 -> 4217243.7 | L6: =(Q21+X21)*$L$42 -> 6090959.7 | M6: =(Q21+X22)*$M$42 -> 7964735.9 | N6: =(Q22+X23)*$N$42 -> 15460509 | O6: =(Q22+X23)*$O$42 -> 22736042 | P6: 1.5 | Q6: 10 a 25 | R6: 92.4 | S6: 118.8 | T6: 145.2 | U6: 158.4 | V6: 184.8 | W6: 0.11 | X6: Coeficiente A4 | Y6: =W6*Y3 -> 18.48 | AB6: 200
A7: 200 | B7: =(Q20+AB20)*$B$42 -> 523932.14 | C7: =(Q20+AB20)*$C$42 -> 523932.14 | D7: =(Q21+AA20)*$D$43 -> 937496.56 | E7: =(Q21+Z21)*$E$43 -> 1405918.1 | F7: =(Q21+Z21)*$F$43 -> 2343196.8 | G7: =(Q21+Z21)*$G$43 -> 3749114.9 | H7: =(Q21+Y21)*$H$43 -> 4217243.7 | I7: =(Q21+Y21)*$I$43 -> 6560156.9 | J7: =(Q21+Y22)*$J$43 -> 7965466.5 | K7: =(Q21+Y22)*$J$43 -> 7965466.5 | L7: =(Q21+X22)*$L$43 -> 11712847 | M7: =(Q22+X23)*$M$43 -> 15460509 | N7: =(Q23+X24)*$N$43 -> 29542282 | O7: =(Q23+X24)*$O$43 -> 44092958 | P7: 1.4 | Q7: 26 a 50 | R7: 85.8 | S7: 112.2 | T7: 138.6 | U7: 151.8 | V7: 178.2 | W7: 0.22 | X7: costo clic color A3 | Y7: =W7*Y3 -> 36.96 | AB7: 300
A8: 300 | B8: =(Q20+AB20)*$B$42 -> 523932.14 | C8: =(Q21+AB20)*$C$44 -> 937676.27 | D8: =(Q21+AA21)*$D$44 -> 1406122.3 | E8: =(Q21+Z21)*$E$44 -> 2343196.8 | F8: =(Q21+Z21)*$F$44 -> 3280475.5 | G8: =(Q21+Z22)*$G$44 -> 5154692.6 | H8: =(Q21+Y22)*$H$44 -> 6091239.1 | I8: =(Q21+Y22)*$I$44 -> 9371137 | J8: =(Q21+Y22)*$J$44 -> 11713921 | K8: =(Q21+Y22)*$J$44 -> 11713921 | L8: =(Q22+X22)*$L$44 -> 17280134 | M8: =(Q22+X23)*$M$44 -> 22736042 | N8: =(Q23+X24)*$N$44 -> 44092958 | O8: =(Q24+X24)*$O$44 -> 64073413 | P8: 1.3 | Q8: 51 a 100 | R8: 79.2 | S8: 105.6 | T8: 132 | U8: 145.2 | V8: 171.6 | W8: 0.22 | X8: costo clic XA3 | Y8: =W8*Y3 -> 36.96
A9: 500 | B9: =(Q20+AB20)*$B$42 -> 523932.14 | C9: =(Q21+AB20)*$C$45 -> 937676.27 | D9: =(Q21+AA21)*$D$45 -> 2343537.2 | E9: =(Q21+Z21)*$E$45 -> 3749114.9 | F9: =(Q21+Z22)*$F$45 -> 5623301.1 | G9: =(Q21+Z22)*$G$45 -> 8434951.6 | H9: =(Q21+Y22)*$H$45 -> 9839693.9 | I9: =(Q22+Y23)*$I$45 -> 15461837 | J9: =(Q23+Y23)*$J$45 -> 18521429 | K9: =(Q23+Y23)*$J$45 -> 18521429 | L9: =(Q23+X23)*$L$45 -> 27779683 | M9: =(Q23+X24)*$M$45 -> 37038085 | N9: =(Q24+X24)*$N$45 -> 71335066 | O9: =(Q24+X24)*$O$45 -> 85431217 | P9: 1.2 | Q9: mas de 100 | R9: 78 | S9: 99 | T9: 125.4 | U9: 138.6 | V9: 165
A10: 1000 | B10: =(Q20+AB20)*$B$42 -> 523932.14 | C10: =(Q21+AB21)*$C$46 -> 1875156.5 | D10: =(Q21+AA21)*$D$46 -> 4218366.9 | E10: =(Q21+Z22)*$E$46 -> 7029126.3 | F10: =(Q21+Z22)*$F$46 -> 10777994 | G10: =(Q22+Z23)*$G$46 -> 16373045 | H10: =(Q22+Y23)*$H$46 -> 19099916 | I10: =(Q23+Y24)*$I$46 -> 29544662 | J10: =(Q23+Y24)*$J$46 -> 37041068 | K10: =(Q23+Y24)*$J$46 -> 37041068 | L10: =(Q24+X24)*$L$46 -> 53394510 | M10: =(Q24+X24)*$M$46 -> 71335066 | N10: =(Q25+X24)*$N$46 -> 1.3806978e+08 | O10: =(Q25+X24)*$O$46 -> 2.0669129e+08 | W10: 0.055555 | X10: costo clic ByN | Y10: =W10*Y3 -> 9.33324 | Z10: 2
R11: SIMPLE | S11: MEDIO | T11: COMPLEJO | U11: MUY COMPLEJO | V11: ULTRA COMPLEJO
P12: 320 | Q12: 1 a 2 | R12: =R4/P12 -> 0.37125 | S12: =S4/P12 -> 0.45375 | T12: =T4/P12 -> 0.53625 | U12: =U4/P12 -> 0.5775 | V12: =V4/P12 -> 0.66
A13: stickers | B13: 1cm. | C13: 2cm. | D13: 3cm. | E13: 4cm. | F13: 5cm. | G13: 6cm. | H13: 7cm. | I13: 8cm. | J13: 9cm. | K13: 10cm | L13: 11cm. | M13: 12-13-14-15cm. | N13: 16/17cm. | O13: 18/19/20cm. | P13: 320 | Q13: 3 a 9 | R13: =R5/P13 -> 0.309375 | S13: =S5/P13 -> 0.391875 | T13: =T5/P13 -> 0.474375 | U13: =U5/P13 -> 0.515625 | V13: =V5/P13 -> 0.598125
A14: 100 | B14: =B6+(T32*B42) -> 524068.4 | C14: =C6+(T32*C42) -> 524068.4 | D14: =D6+(T32*D42) -> 523978.54 | E14: =E6+(T32*E42) -> 937619.33 | F14: =F6+(T32*F42) -> 1406326.9 | G14: =G6+(T32*G42) -> 1875102.5 | H14: =H6+(T32*H42) -> 2343594.5 | I14: =I6+(T32*I42) -> 3281032.3 | J14: =J6+(T32*J42) -> 4218470.1 | K14: =K6+(T32*K42) -> 4218470.1 | L14: =L6+(T32*L42) -> 6092731.1 | M14: =M6+(T32*M42) -> 7967052.4 | N14: =N6+(T32*N42) -> 15465142 | O14: =O6+(T33*O42) -> 22742344 | P14: 320 | Q14: 10 a 25 | R14: =R6/P14 -> 0.28875 | S14: =S6/P14 -> 0.37125 | T14: =T6/P14 -> 0.45375 | U14: =U6/P14 -> 0.495 | V14: =V6/P14 -> 0.5775
A15: 200 | B15: =B7+(T32*B43) -> 524068.4 | C15: =C7+(T32*C43) -> 524068.4 | D15: =D7+(T32*D43) -> 937769.09 | E15: =E7+(T32*E43) -> 1406326.9 | F15: =F7+(T32*F43) -> 2343878.1 | G15: =G7+(T32*G43) -> 3750205 | H15: =H7+(T32*H43) -> 4218470.1 | I15: =I7+(T33*I43) -> 6561921.5 | J15: =J7+(T33*J43) -> 7967609.2 | K15: =K7+(T33*K43) -> 7967609.2 | L15: =L7+(T33*L43) -> 11715998 | M15: =M7+(T33*M43) -> 15464794 | N15: =N7+(T33*N43) -> 29550727 | O15: =O7+(T34*O43) -> 44104541 | P15: 320 | Q15: 26 a 50 | R15: =R7/P15 -> 0.268125 | S15: =S7/P15 -> 0.350625 | T15: =T7/P15 -> 0.433125 | U15: =U7/P15 -> 0.474375 | V15: =V7/P15 -> 0.556875
A16: 300 | B16: =B8+(T32*B44) -> 524068.4 | C16: =C8+(T32*C44) -> 937948.8 | D16: =D8+(T32*D44) -> 1406531.1 | E16: =E8+(T32*E44) -> 2343878.1 | F16: =F8+(T32*F44) -> 3281429.4 | G16: =G8+(T33*G44) -> 5156079.1 | H16: =H8+(T33*H44) -> 6092877.6 | I16: =I8+(T33*I44) -> 9373657.9 | J16: =J8+(T33*J44) -> 11717072 | K16: =K8+(T33*K44) -> 11717072 | L16: =L8+(T33*L44) -> 17284924 | M16: =M8+(T34*M44) -> 22741833 | N16: =N8+(T34*N44) -> 44104541 | O16: =O8+(T34*O44) -> 64090786 | P16: 320 | Q16: 51 a 100 | R16: =R8/P16 -> 0.2475 | S16: =S8/P16 -> 0.33 | T16: =T8/P16 -> 0.4125 | U16: =U8/P16 -> 0.45375 | V16: =V8/P16 -> 0.53625
A17: 500 | B17: =B9+(T32*B45) -> 524068.4 | C17: =C9+(T32*C45) -> 937948.8 | D17: =D9+(T32*D45) -> 2344218.5 | E17: =E9+(T32*E45) -> 3750205 | F17: =F9+(T33*F45) -> 5624813.6 | G17: =G9+(T33*G45) -> 8437220.4 | H17: =H9+(T33*H45) -> 9842340.8 | I17: =I9+(T33*I45) -> 15466122 | J17: =J9+(T33*J45) -> 18526723 | K17: =K9+(T33*K45) -> 18526723 | L17: =L9+(T34*L45) -> 27786979 | M17: =M9+(T34*M45) -> 37047814 | N17: =N9+(T34*N45) -> 71354408 | O17: =O9+(T35*O45) -> 85452337 | P17: 320 | Q17: mas de 100 | R17: =R9/P17 -> 0.24375 | S17: =S9/P17 -> 0.309375 | T17: =T9/P17 -> 0.391875 | U17: =U9/P17 -> 0.433125 | V17: =V9/P17 -> 0.515625 | X17: 1 | Y17: 2 | Z17: 1.2 | AA17: 1.2 | AB17: 1.2
A18: 1000 | B18: =B10+(T32*B46) -> 524068.4 | C18: =C10+(T32*C46) -> 1875701.5 | D18: =D10+(T32*D46) -> 4219593.3 | E18: =E10+(T33*E46) -> 7031017 | F18: =F10+(T33*F46) -> 10780893 | G18: =G10+(T33*G46) -> 16377582 | H18: =H10+(T33*H46) -> 19105210 | I18: =I10+(T34*I46) -> 29552422 | J18: =J10+(T34*J46) -> 37050798 | K18: =K10+(T34*K46) -> 37050798 | L18: =L10+(T35*L46) -> 53407711 | M18: =M10+(T35*M46) -> 71352702 | N18: =N10+(T35*N46) -> 1.3810505e+08 | O18: =O10+(T35*O46) -> 2.0674409e+08 | T18: hoja | U18: 29 | V18: 44 | X18: mas de 15x15 cm. | Y18: de 10x10 a 14x14 cm | Z18: de 5x5 a 9x9 cm, | AA18: de2x2 a 4x4 cm, | AB18: de 1x1 a 2x2cm. | AE18: PAPEL | AF18: opp | AG18: 5to color
Q19: Sticker | S19: x pliegos | T19: cm2 | U19: TROQUELADO | V19: GEMINI | W19: medio corte | X19: simple | Y19: medio | Z19: complejo | AA19: muy complejo | AB19: ultra complejo | AC19: CM | AE19: =Bajadas!S4 -> 523393 | AF19: =Bajadas!U4 -> 1341.8275 | AG19: =Bajadas!AT38 -> 370.5
Q20: =Bajadas!S4 -> 523393 | R20: 1 | S20: 1 | T20: cm2 | U20: =U18*V18 -> 1276 | V20: minimo | W20: 1 a 2 | X20: 260 | Y20: =X20*Z17 -> 312 | Z20: =Y20*Z17 -> 374.4 | AA20: =Z20*AA17 -> 449.28 | AB20: =AA20*AB17 -> 539.136 | AC20: 387 | AE20: =Bajadas!S5 -> 468299 | AF20: =Bajadas!U5 -> 1200.5825 | AG20: =Bajadas!AT39 -> 351
A21: calcos | B21: 1cm. | C21: 2cm. | D21: 3cm. | E21: 4cm. | F21: 5cm. | G21: 6cm. | H21: 7cm. | I21: 8cm. | J21: 9cm. | K21: 10cm | L21: 11cm. | M21: 12-13-14-15cm. | N21: 16/17cm. | O21: 18/19/20cm. | Q21: =Bajadas!S5 -> 468299 | R21: 2 a 25 | S21: 1 | T21: cm2 | U21: =U20 -> 1276 | V21: 1.1 | W21: 3 a 9 | X21: =X20/V22 -> 236.36364 | Y21: =Y20/V22 -> 283.63636 | Z21: =Z20/V22 -> 340.36364 | AA21: =AA20/V22 -> 408.43636 | AB21: =AB20/V22 -> 490.12364 | AC21: 352 | AE21: =Bajadas!S6 -> 454525.5 | AF21: =Bajadas!U6 -> 1165.2713 | AG21: =Bajadas!AT40 -> 331.5
A22: 100 | B22: =(Q32+AB45)*$B$42 -> 2042.7043 | C22: =(Q32+AB45)*$C$42 -> 2042.7043 | D22: =(Q32+AA45)*$D$42 -> 1925.8915 | E22: =(Q32+Z45)*$E$42 -> 3657.095 | F22: =(Q33+Z46)*$F$42 -> 4929.1657 | G22: =(Q33+Z46)*$G$42 -> 6572.2209 | H22: =(Q33+Y46)*$H$42 -> 7846.5489 | I22: =(Q33+Y46)*$I$42 -> 10985.168 | J22: =(Q33+Y46)*$J$42 -> 14123.788 | K22: =(Q33+Y46)*$J$42 -> 14123.788 | L22: =(Q33+X47)*$L$42 -> 19238.977 | M22: =(Q33+X47)*$M$42 -> 25158.663 | N22: =(Q34+X48)*$N$42 -> 48253.332 | O22: =(Q39+X48)*$O$42 -> 62132.97 | Q22: =Bajadas!S6 -> 454525.5 | R22: 26 a 50 | S22: 1 | T22: cm2 | U22: =U21 -> 1276 | V22: 1.1 | W22: 10 a 25 | X22: =X21/V23 -> 214.87603 | Y22: =Y21/V23 -> 257.85124 | Z22: =Z21/V23 -> 309.42149 | AA22: =AA21/V23 -> 371.30579 | AB22: =AB21/V23 -> 445.56694 | AC22: 320 | AE22: =Bajadas!S7 -> 440752 | AF22: =Bajadas!U7 -> 1129.96 | AG22: =Bajadas!AT41 -> 312
A23: 200 | B23: =(Q32+AB45)*$B$42 -> 2042.7043 | C23: =(Q32+AB45)*$C$43 -> 2042.7043 | D23: =(Q32+AA45)*$D$43 -> 3851.783 | E23: =(Q33+Z46)*$E$43 -> 4929.1657 | F23: =(Q33+Z46)*$F$43 -> 8215.2761 | G23: =(Q33+Z46)*$G$43 -> 13144.442 | H23: =(Q33+Y46)*$H$43 -> 14123.788 | I23: =(Q33+Y47)*$I$43 -> 21501.048 | J23: =(Q33+Y47)*$J$43 -> 26108.415 | K23: =(Q33+Y47)*$J$43 -> 26108.415 | L23: =(Q33+X47)*$L$43 -> 36998.034 | M23: =(Q34+X48)*$M$43 -> 48253.332 | N23: =(Q35+X49)*$N$43 -> 91174.843 | O23: =(Q35+X49)*$O$43 -> 136081.85 | Q23: =Bajadas!S7 -> 440752 | R23: 51 a 100 | S23: 1 | T23: cm2 | U23: =U22 -> 1276 | V23: 1.1 | W23: 26 a 50 | X23: =X22/V24 -> 195.34185 | Y23: =Y22/V24 -> 234.41022 | Z23: =Z22/V24 -> 281.29226 | AA23: =AA22/V24 -> 337.55071 | AB23: =AB22/V24 -> 405.06086 | AC23: 291 | AE23: =Bajadas!S8 -> 426978.5 | AF23: =Bajadas!U8 -> 1094.6488 | AG23: =Bajadas!AT42 -> 292.5
A24: 300 | B24: =(Q32+AB45)*$B$42 -> 2042.7043 | C24: =(Q33+AB45)*$C$44 -> 3802.9186 | D24: =(Q33+AA46)*$D$44 -> 5194.6493 | E24: =(Q33+Z46)*$E$44 -> 8215.2761 | F24: =(Q33+Z46)*$F$44 -> 11501.387 | G24: =(Q33+Z47)*$G$44 -> 17631.135 | H24: =(Q33+Y47)*$H$44 -> 19965.258 | I24: =(Q33+Y47)*$I$44 -> 30715.782 | J24: =(Q33+Y47)*$J$44 -> 38394.728 | K24: =(Q33+Y47)*$J$44 -> 38394.728 | L24: =(Q34+X48)*$L$44 -> 53930.195 | M24: =(Q34+X48)*$M$44 -> 70960.783 | N24: =(Q35+X49)*$N$44 -> 136081.85 | O24: =(Q36+X49)*$O$44 -> 198826.09 | Q24: =Bajadas!S8 -> 426978.5 | R24: 101 a 300 | S24: 1 | T24: cm2 | U24: =U23 -> 1276 | V24: 1.1 | W24: 51 a 100 | X24: =X23/V25 -> 177.5835 | Y24: =Y23/V25 -> 213.1002 | Z24: =Z23/V25 -> 255.72024 | AA24: =AA23/V25 -> 306.86429 | AB24: =AB23/V25 -> 368.23714 | AC24: 264 | AE24: =Bajadas!S9 -> 413205 | AF24: =Bajadas!U9 -> 1059.3375 | AG24: =Bajadas!AT43 -> 273
A25: 500 | B25: =(Q32+AB45)*$B$42 -> 2042.7043 | C25: =(Q33+AB45)*$C$45 -> 3802.9186 | D25: =(Q33+AA46)*$D$45 -> 8657.7489 | E25: =(Q33+Z46)*$E$45 -> 13144.442 | F25: =(Q33+Z47)*$F$45 -> 19233.965 | G25: =(Q33+Z47)*$G$45 -> 28850.948 | H25: =(Q33+Y47)*$H$45 -> 32251.571 | I25: =(Q34+Y48)*$I$45 -> 49980.154 | J25: =(Q34+Y48)*$J$45 -> 61740.19 | K25: =(Q34+Y48)*$J$45 -> 61740.19 | L25: =(Q35+X49)*$L$45 -> 85731.569 | M25: =(Q35+X49)*$M$45 -> 114308.76 | N25: =(Q36+X49)*$N$45 -> 221359.72 | O25: =(Q36+X49)*$O$45 -> 265101.46 | Q25: =Bajadas!S9 -> 413205 | R25: 301 a 500 | S25: 1 | U25: =U24 -> 1276 | V25: 1.1 | W25: mas de 100 | X25: =X24/V25 -> 161.43954 | Y25: =Y24/V26 -> 193.72745 | Z25: =Z24/V26 -> 232.47294 | AA25: =AA24/V26 -> 278.96753 | AB25: =AB24/V26 -> 334.76104 | AC25: 240 | AE25: =Bajadas!S10 -> 399431.5 | AF25: =Bajadas!U10 -> 1024.0262 | AG25: =Bajadas!AT44 -> 253.5
A26: 1000 | B26: =(Q37+AB45)*$B$42 -> 1760.2143 | C26: =(Q33+AB46)*$C$46 -> 7350.9729 | D26: =(Q33+AA46)*$D$46 -> 15583.948 | E26: =(Q33+Z47)*$E$46 -> 24042.457 | F26: =(Q33+Z47)*$F$46 -> 36865.1 | G26: =(Q34+Z48)*$G$46 -> 55114.243 | H26: =(Q34+Y48)*$H$46 -> 61740.19 | I26: =(Q35+Y49)*$I$46 -> 94268.347 | J26: =(Q35+Y49)*$J$46 -> 118187.18 | K26: =(Q35+Y49)*$J$46 -> 118187.18 | L26: =(Q36+X49)*$L$46 -> 165688.41 | M26: =(Q36+X49)*$M$46 -> 221359.72 | N26: =(Q37+X49)*$N$46 -> 430925.48 | O26: =(Q37+X49)*$O$46 -> 645098.02 | Q26: =Bajadas!S10 -> 399431.5 | R26: 501 a 1000 | S26: 1 | V26: 1.1
Q27: =Bajadas!S11 -> 385658 | R27: 1000
S28: 1 | V28: cm2 | W28: medio corte | X28: simple | Y28: medio | Z28: complejo | AA28: muy complejo | AB28: ultra complejo | AE28: sticker | AF28: opp | AG28: 5to color
W29: 1 a 2 | X29: =X20/U20 -> 0.20376176 | Y29: =Y20/U20 -> 0.24451411 | Z29: =Z20/U20 -> 0.29341693 | AA29: =AA20/U20 -> 0.35210031 | AB29: =AB20/U20 -> 0.42252038 | AE29: =AE19/U20 -> 410.1826 | AF29: =AF19/U20 -> 1.0515889 | AG29: =AG19/U20 -> 0.2903605
A30: calcos | B30: 1cm. | C30: 2cm. | D30: 3cm. | E30: 4cm. | F30: 5cm. | G30: 6cm. | H30: 7cm. | I30: 8cm. | J30: 9cm. | K30: 10cm | L30: 11cm. | M30: 12-13-14-15cm. | N30: 16/17cm. | O30: 18/19/20cm. | Q30: =Bajadas!U2 -> OPP blco o blanco | W30: 3 a 9 | X30: =X21/U20 -> 0.18523796 | Y30: =Y21/U20 -> 0.22228555 | Z30: =Z21/U20 -> 0.26674266 | AA30: =AA21/U20 -> 0.32009119 | AB30: =AB21/U20 -> 0.38410943 | AE30: =AE20/U21 -> 367.00549 | AF30: =AF20/U21 -> 0.94089538 | AG30: =AG20/U21 -> 0.27507837
A31: 100 | B31: =B23+(T32*B59) -> 2178.967 | C31: =C23+(T32*C59) -> 2178.967 | D31: =D22+(T32*D59) -> 2062.1542 | E31: =E22+(T32*E59) -> 3929.6204 | F31: =F22+(T33*F59) -> 5307.2947 | G31: =G22+(T33*G59) -> 7076.3929 | H31: =H22+(T33*H59) -> 8476.7639 | I31: =I22+(T33*I59) -> 11867.469 | J31: =J22+(T33*J59) -> 15258.175 | K31: =K22+(T33*K59) -> 15258.175 | L31: =L22+(T33*L59) -> 20877.536 | M31: =M22+(T33*M59) -> 27301.394 | N31: =N22+(T33*N59) -> 52538.794 | O31: =O22+(T33*O59) -> 68435.12 | T31: laca uv | W31: 10 a 25 | X31: =X22/U20 -> 0.16839814 | Y31: =Y22/U20 -> 0.20207777 | Z31: =Z22/U20 -> 0.24249333 | AA31: =AA22/U20 -> 0.29099199 | AB31: =AB22/U20 -> 0.34919039 | AE31: =AE21/U22 -> 356.21121 | AF31: =AF21/U22 -> 0.91322198 | AG31: =AG21/U22 -> 0.25979624
A32: 200 | B32: =B24+(T32*B60) -> 2178.967 | C32: =C23+(T32*C60) -> 2178.967 | D32: =D23+(T32*D60) -> 4124.3084 | E32: =E23+(T33*E60) -> 5307.2947 | F32: =F23+(T33*F60) -> 8845.4911 | G32: =G23+(T33*G60) -> 14152.786 | H32: =H23+(T33*H60) -> 15258.175 | I32: =I23+(T33*I60) -> 23265.65 | J32: =J23+(T33*J60) -> 28251.146 | K32: =K23+(T33*K60) -> 28251.146 | L32: =L23+(T33*L60) -> 40149.109 | M32: =M23+(T33*M60) -> 52538.794 | N32: =N23+(T34*N60) -> 98935.004 | O32: =O23+(T34*O60) -> 147664.18 | Q32: =Bajadas!U4 -> 1341.8275 | R32: 1 | S32: 1 a 10 | T32: =Laminado!E7 -> 136.2627 | W32: 26 a 50 | X32: =X23/U20 -> 0.15308922 | Y32: =Y23/U20 -> 0.18370707 | Z32: =Z23/U20 -> 0.22044848 | AA32: =AA23/U20 -> 0.26453818 | AB32: =AB23/U20 -> 0.31744581 | AE32: =AE22/U23 -> 345.41693 | AF32: =AF22/U23 -> 0.88554859 | AG32: =AG22/U23 -> 0.24451411
A33: 300 | B33: =B25+(T32*B61) -> 2178.967 | C33: =C24+(T33*C61) -> 4055.0046 | D33: =D24+(T33*D61) -> 5572.7783 | E33: =E24+(T33*E61) -> 8845.4911 | F33: =F24+(T33*F61) -> 12383.688 | G33: =G24+(T33*G61) -> 19017.608 | H33: =H24+(T33*H61) -> 21603.817 | I33: =I24+(T33*I61) -> 33236.642 | J33: =J24+(T33*J61) -> 41545.803 | K33: =K24+(T33*K61) -> 41545.803 | L33: =L24+(T33*L61) -> 58719.829 | M33: =M24+(T33*M61) -> 77262.933 | N33: =N24+(T34*N61) -> 147664.18 | O33: =O24+(T35*O61) -> 214666.63 | Q33: =Bajadas!U5 -> 1200.5825 | R33: 2 a 25 | S33: 11 a 50 | T33: =Laminado!E8 -> 126.043 | W33: 51 a 100 | X33: =X24/U20 -> 0.13917202 | Y33: =Y24/U20 -> 0.16700642 | Z33: =Z24/U20 -> 0.20040771 | AA33: =AA24/U20 -> 0.24048925 | AB33: =AB24/U20 -> 0.2885871 | AE33: =AE23/U24 -> 334.62265 | AF33: =AF23/U24 -> 0.8578752 | AG33: =AG23/U24 -> 0.22923197
A34: 500 | B34: =B25+(T32*B62) -> 2178.967 | C34: =C25+(T33*C62) -> 4055.0046 | D34: =D25+(T33*D62) -> 9287.9639 | E34: =E25+(T33*E62) -> 14152.786 | F34: =F25+(T33*F62) -> 20746.481 | G34: =G25+(T33*G62) -> 31119.722 | H34: =H25+(T33*H62) -> 34898.474 | I34: =I25+(T33*I62) -> 54265.616 | J34: =J25+(T33*J62) -> 67033.996 | K34: =K25+(T33*K62) -> 67033.996 | L34: =L25+(T33*L62) -> 93672.278 | M34: =M25+(T34*M62) -> 124037.92 | N34: =N25+(T35*N62) -> 238995.52 | O34: =O25+(T36*O62) -> 284859.55 | Q34: =Bajadas!U6 -> 1165.2713 | R34: 26 a 50 | S34: 51 a 100 | T34: =Laminado!E9 -> 115.8233 | W34: mas de 100 | X34: =X25/U21 -> 0.12652002 | Y34: =Y25/U21 -> 0.15182402 | Z34: =Z25/U21 -> 0.18218883 | AA34: =AA25/U21 -> 0.21862659 | AB34: =AB25/U21 -> 0.26235191 | AC34: 0.2529 | AE34: =AE24/U25 -> 323.82837 | AF34: =AF24/U25 -> 0.8302018 | AG34: =AG24/U25 -> 0.21394984 | AH34: 0.88
A35: 1000 | B35: =B26+(T32*B63) -> 1896.477 | C35: =C26+(T33*C63) -> 7855.1449 | D35: =D26+(T33*D63) -> 16592.292 | E35: =E26+(T33*E63) -> 25933.102 | F35: =F26+(T33*F63) -> 39764.089 | G35: =G26+(T33*G63) -> 59651.791 | H35: =H26+(T33*H63) -> 67033.996 | I35: =I26+(T34*I63) -> 102028.51 | J35: =J26+(T34*J63) -> 127916.34 | K35: =K26+(T34*K63) -> 127916.34 | L35: =L26+(T35*L63) -> 178888.86 | M35: =M26+(T35*M63) -> 238995.52 | N35: =N26+(T36*N63) -> 463921.49 | O35: =O26+(T37*O63) -> 691086.69 | Q35: =Bajadas!U7 -> 1129.96 | R35: 51 a 100 | S35: 100 | T35: =Laminado!E10 -> 105.6036
Q36: =Bajadas!U8 -> 1094.6488 | R36: 101 a 300 | T36: =Laminado!E11 -> 98.790461
Q37: =Bajadas!U9 -> 1059.3375 | R37: 301 a 500 | T37: =Laminado!E12 -> 91.977326
Q38: =Bajadas!U10 -> 1024.0262 | R38: 501 a 1000 | T38: =Laminado!E13 -> 85.16419
Q39: =Bajadas!U11 -> 988.715 | R39: 1000
B40: 1204 | C40: 294 | D40: 117 | E40: 70 | F40: 45 | G40: 28 | H40: 24 | I40: 15 | J40: 12 | K40: 12 | L40: 8 | M40: 6 | N40: 3 | O40: 2 | Q40: =Bajadas!U12
...

Sheet Bajadas
B1: BAJADAS | W1: tienda | AA1: 2 | AD1: 0.6 | AG1: 1.5 | AJ1: 0.6
B2: A3+ (32x47) | C2: Triplex | E2: 350g | G2: 300g | I2: 200g | K2: 150g | M2: 115g | O2: 90g | Q2: 80 grs | S2: Sticker | T2: Imán | U2: OPP blco o blanco | W2: 350 | AA2: Precio del papel por hoja | AG2: Precio del papel por hoja
B3: 30x46 | C3: 4/0 | D3: 4/4 | E3: 4/0 | F3: 4/4 | G3: 4/0 | H3: 4/4 | I3: 4/0 | J3: 4/4 | K3: 4/0 | L3: 4/4 | M3: 4/0 | N3: 4/4 | O3: 4/0 | P3: 4/4 | Q3: 4/0 | R3: 4/4 | S3: 4/0 | T3: 4/0 | U3: 4/0 | Z3: Precio de papel | AA3: XL | AB3: 33X48 | AC3: 32X47 | AD3: A4 | AF3: Precio de papel | AG3: XL | AH3: 33X48 | AI3: 32X47 | AJ3: A4
B4: 1 | C4: =(AC48+AC11)*$AH$48 -> 226922.93 | D4: =(AC48*AG48+AC11)*AH48 -> 227182.28 | E4: =(AC48+AC4)*$AH$48 -> 226446.98 | F4: =(AC48*AG48+AC4)*AH48 -> 226706.33 | G4: =(AC48+AC5)*$AH$48 -> 194150.34 | H4: =(AC48*AG48+AC5)*AH48 -> 194409.69 | I4: =(AC48+AC6)*$AH$48 -> 142475.71 | J4: =(AC48*AG48+AC6)*AH48 -> 142735.06 | K4: =(AC48+AC7)*$AH$48 -> 97260.418 | L4: =(AC48*AG48+AC7)*AH48 -> 97519.768 | M4: =(AC48+AC8)*$AH$48 -> 74652.771 | N4: =(AC48*AG48+AC8)*AH48 -> 74912.121 | O4: =(AC48+AC9)*AH$48 -> 58504.451 | P4: =(AC48*AG48+AC9)*AH48 -> 58763.801 | Q4: =(AC48+AC10)*AH$48 -> 58504.451 | R4: =(AC48*AG48+AC10)*AH48 -> 58763.801 | S4: =(AC48+AC12)*AH48 -> 523393 | T4: =(AC48+$AC$14)*AH48+AC5 -> 104248.03 | U4: =(AC48+$AC$13*AF48)*AH48 -> 1341.8275 | W4: 460 | X4: 588 | Z4: 350g | AA4: =AG4*$AM$38*AA18 -> 212270.06 | AB4: =AH4*$AM$38 -> 141513.37 | AC4: =AI4*$AM$38*AC18 -> 118987.62 | AD4: =AJ4*$AM$38 -> 71392.571 | AE4: =AC4 -> 118987.62 | AF4: 350g | AG4: =AH4*$AG$1 -> 326.56932 | AH4: ='PAPEL US$'!I24 -> 217.71288 | AI4: ='PAPEL US$'!J23 -> 183.05787 | AJ4: =AI4*$AJ$1 -> 109.83473 | AN4: 28 | AO4: 71 | AQ4: 2.2
B5: 2 a 25 | C5: =(AC49+AC11)*$AH$49 -> 203036.3 | D5: =(AC49*AG49+AC11)*AH49 -> 203268.35 | E5: =(AC49+AC4)*AH$49 -> 202610.45 | F5: =(AC49*AG49+AC4)*AH49 -> 202842.5 | G5: =(AC49+AC5)*$AH$49 -> 173713.46 | H5: =(AC49*AG49+AC5)*AH49 -> 173945.51 | I5: =(AC49+AC6)*$AH$49 -> 127478.27 | J5: =(AC49*AG49+AC6)*AH49 -> 127710.32 | K5: =(AC49+AC7)*$AH$49 -> 87022.479 | L5: =(AC49*AG49+AC7)*AH49 -> 87254.529 | M5: =(AC49+AC8)*$AH$49 -> 66794.584 | N5: =(AC49*AG49+AC8)*AH49 -> 67026.634 | O5: =(AC49+AC9)*AH$49 -> 52346.088 | P5: =(AC49*AG49+AC9)*AH49 -> 52578.138 | Q5: =(AC49+AC10)*AH$49 -> 52346.088 | R5: =(AC49*AG49+AC9)*AH49 -> 52578.138 | S5: =(AC49+$AC$12*AF49)*$AH$49 -> 468299 | T5: =(AC49+$AC$14)*AH49+AC5 -> 104010.28 | U5: =(AC49+$AC$13*AF49)*AH49 -> 1200.5825 | W5: 436 | X5: 557 | Z5: 300g | AA5: =AG5*$AM$38 -> 181945.76 | AB5: =AH5*$AM$38 -> 121297.18 | AC5: =AI5*$AM$38*AC19 -> 101989.39 | AD5: =AJ5*$AM$38 -> 61193.632 | AE5: =AC5 -> 101989.39 | AF5: 300g | AG5: =AH5*$AG$1 -> 279.91656 | AH5: ='PAPEL US$'!I21 -> 186.61104 | AI5: ='PAPEL US$'!J20 -> 156.90675 | AJ5: =AI5*$AJ$1 -> 94.14405 | AQ5: 2
B6: 26 a 50 | C6: =(AC50+AC11)*$AH$50 -> 197064.65 | D6: =(AC50*AG50+AC11)*AH50 -> 197289.87 | E6: =(AC50+AC4)*AH$50 -> 196651.32 | F6: =(AC50*AG50+AC4)*AH50 -> 196876.55 | G6: =(AC50+AC5)*$AH$50 -> 168604.24 | H6: =(AC50*AG50+AC5)*AH50 -> 168829.46 | I6: =(AC50+AC6)*$AH$50 -> 123728.91 | J6: =(AC50*AG50+AC6)*AH50 -> 123954.13 | K6: =(AC50+AC7)*$AH$50 -> 84462.995 | L6: =(AC50*AG50+AC7)*AH50 -> 84688.22 | M6: =(AC50+AC8)*$AH$50 -> 64830.038 | N6: =(AC50*AG50+AC8)*AH50 -> 65055.263 | O6: =(AC50+AC9)*AH$50 -> 50806.497 | P6: =(AC50*AG50+AC9)*AH50 -> 51031.722 | Q6: =(AC50+AC10)*AH$50 -> 50806.497 | R6: =(AC50*AG50+AC10)*AH50 -> 51031.722 | S6: =(AC50+$AC$12*AF50)*$AH$50 -> 454525.5 | T6: =(AC50+$AC$14)*AH50+AC5 -> 103950.84 | U6: =(AC50+$AC$13*AF50)*AH50 -> 1165.2713 | W6: 412 | X6: 526 | Z6: 200g | AA6: =AG6*$AM$38 -> 133426.89 | AB6: =AH6*$AM$38 -> 88951.262 | AC6: =AI6*$AM$38*AC20 -> 74792.217 | AD6: =AJ6*$AM$38 -> 44875.33 | AE6: =AC6 -> 74792.217 | AF6: 200g | AG6: =AH6*$AG$1 -> 205.27214 | AH6: ='PAPEL US$'!I18 -> 136.8481 | AI6: ='PAPEL US$'!J13 -> 115.06495 | AJ6: =AI6*$AJ$1 -> 69.03897 | AQ6: 1.8
B7: 51 a 100 | C7: =(AC51+AC11)*$AH$51 -> 191092.99 | D7: =(AC51*AG51+AC11)*AH51 -> 191311.39 | E7: =(AC51+AC4)*AH$51 -> 190692.19 | F7: =(AC51*AG51+AC4)*AH51 -> 190910.59 | G7: =(AC51+AC5)*$AH$51 -> 163495.02 | H7: =(AC51*AG51+AC5)*AH51 -> 163713.42 | I7: =(AC51+AC6)*$AH$51 -> 119979.55 | J7: =(AC51*AG51+AC6)*AH51 -> 120197.95 | K7: =(AC51+AC7)*$AH$51 -> 81903.51 | L7: =(AC51*AG51+AC7)*AH51 -> 82121.91 | M7: =(AC51+AC8)*$AH$51 -> 62865.491 | N7: =(AC51*AG51+AC8)*AH51 -> 63083.891 | O7: =(AC51+AC9)*AH$51 -> 49266.906 | P7: =(AC51*AG51+AC9)*AH51 -> 49485.306 | Q7: =(AC51+AC10)*AH$51 -> 49266.906 | R7: =(AC51*AG51+AC10)*AH51 -> 49485.306 | S7: =(AC51+$AC$12*AF51)*$AH$51 -> 440752 | T7: =(AC51+$AC$14)*AH51+AC5 -> 103891.4 | U7: =(AC51+$AC$13*AF51)*AH51 -> 1129.96 | W7: 388 | X7: 495 | Z7: 150g | AA7: =AG7*$AM$38 -> 90972.882 | AB7: =AH7*$AM$38 -> 60648.588 | AC7: =AI7*$AM$38*AC21 -> 50994.694 | AD7: =AJ7*$AM$38 -> 30596.816 | AE7: =AC7 -> 50994.694 | AF7: 150g | AG7: =AH7*$AG$1 -> 139.95828 | AH7: ='PAPEL US$'!I17 -> 93.30552 | AI7: ='PAPEL US$'!J12 -> 78.453375 | AJ7: =AI7*$AJ$1 -> 47.072025 | AQ7: 1.7
B8: 101 a 300 | C8: =(AC52+AC11)*AH$52 -> 185121.33 | D8: =(AC52*AG52+AC11)*AH52 -> 185332.91 | E8: =(AC52+AC4)*AH$52 -> 184733.06 | F8: =(AC52*AG52+AC4)*AH52 -> 184944.63 | G8: =(AC52+AC5)*$AH$52 -> 158385.8 | H8: =(AC52*AG52+AC5)*AH52 -> 158597.38 | I8: =(AC52+AC6)*$AH$52 -> 116230.19 | J8: =(AC52*AG52+AC6)*AH52 -> 116441.76 | K8: =(AC52+AC7)*$AH$52 -> 79344.025 | L8: =(AC52*AG52+AC7)*AH52 -> 79555.6 | M8: =(AC52+AC8)*$AH$52 -> 60900.944 | N8: =(AC52*AG52+AC8)*AH52 -> 61112.519 | O8: =(AC52+AC9)*AH$52 -> 47727.315 | P8: =(AC52*AG52+AC9)*AH52 -> 47938.89 | Q8: =(AC52+AC10)*AH$52 -> 47727.315 | R8: =(AC52*AG52+AC10)*AH52 -> 47938.89 | S8: =(AC52+$AC$12*AF52)*$AH$52 -> 426978.5 | T8: =(AC52+$AC$14)*AH52+AC5 -> 103831.97 | U8: =(AC52+$AC$13*AF52)*AH52 -> 1094.6488 | W8: 363 | X8: 464 | Z8: 115g | AA8: =AG8*$AM$38 -> 69745.876 | AB8: =AH8*$AM$38 -> 46497.251 | AC8: =AI8*$AM$38*AC22 -> 39095.932 | AD8: =AJ8*$AM$38 -> 23457.559 | AE8: =AC8 -> 39095.932 | AF8: 115g | AG8: =AH8*$AG$1 -> 107.30135 | AH8: ='PAPEL US$'!I16 -> 71.534232 | AI8: ='PAPEL US$'!J11 -> 60.147588 | AJ8: =AI8*$AJ$1 -> 36.088552
B9: 301 a 500 | C9: =(AC53+AC11)*AH$53 -> 179149.68 | D9: =(AC53*AG52+AC11)*AH53 -> 179354.43 | E9: =(AC53+AC4)*AH$53 -> 178773.93 | F9: =(AC53*AG53+AC4)*AH53 -> 178978.68 | G9: =(AC53+AC5)*$AH$53 -> 153276.58 | H9: =(AC53*AG53+AC5)*AH53 -> 153481.33 | I9: =(AC53+AC6)*$AH$53 -> 112480.83 | J9: =(AC53*AG53+AC6)*AH53 -> 112685.58 | K9: =(AC53+AC7)*$AH$53 -> 76784.541 | L9: =(AC53*AG53+AC7)*AH53 -> 76989.291 | M9: =(AC53+AC8)*$AH$53 -> 58936.398 | N9: =(AC53*AG53+AC8)*AH53 -> 59141.148 | O9: =(AC53+AC9)*AH$53 -> 46187.724 | P9: =(AC53*AG53+AC9)*AH53 -> 46392.474 | Q9: =(AC53+AC10)*AH$53 -> 46187.724 | R9: =(AC53*AG53+AC10)*AH53 -> 46392.474 | S9: =(AC53+$AC$12*AF53)*$AH$53 -> 413205 | T9: =(AC53+$AC$14)*AH53+AC5 -> 103772.53 | U9: =(AC53+$AC$13*AF53)*AH53 -> 1059.3375 | W9: 339 | X9: 433 | Z9: 90g | AA9: =AG9*$AM$38 -> 54583.729 | AB9: =AH9*$AM$38 -> 36389.153 | AC9: =AI9*$AM$38*AC23 -> 30596.816 | AD9: =AJ9*$AM$38 -> 18358.09 | AE9: =AC9 -> 30596.816 | AF9: 90g | AG9: =AH9*$AG$1 -> 83.974968 | AH9: ='PAPEL US$'!I15 -> 55.983312 | AI9: ='PAPEL US$'!J10 -> 47.072025 | AJ9: =AI9*$AJ$1 -> 28.243215
B10: 501 a 1000 | C10: =(AC54+AC11)*AH$54 -> 173178.02 | D10: =(AC54*AG54+AC11)*AH54 -> 173375.95 | E10: =(AC54+AC4)*AH$54 -> 172814.8 | F10: =(AC54*AG54+AC4)*AH54 -> 173012.72 | G10: =(AC54+AC5)*$AH$54 -> 148167.36 | H10: =(AC54*AG54+AC5)*AH54 -> 148365.29 | I10: =(AC54+AC6)*$AH$54 -> 108731.47 | J10: =(AC54*AG54+AC6)*AH54 -> 108929.39 | K10: =(AC54+AC7)*$AH$54 -> 74225.056 | L10: =(AC54*AG54+AC7)*AH54 -> 74422.981 | M10: =(AC54+AC8)*$AH$54 -> 56971.851 | N10: =(AC54*AG54+AC8)*AH54 -> 57169.776 | O10: =(AC54+AC9)*AH$54 -> 44648.134 | P10: =(AC54*AG54+AC9)*AH54 -> 44846.059 | Q10: =(AC54+AC10)*AH$54 -> 44648.134 | R10: =(AC54*AG54+AC10)*AH54 -> 44846.059 | S10: =(AC54+$AC$12*AF54)*$AH$54 -> 399431.5 | T10: =(AC54+$AC$14)*AH54+AC5 -> 103713.09 | U10: =(AC54+$AC$13*AF54)*AH54 -> 1024.0262 | W10: 315 | X10: 402 | Z10: Obra | AA10: =AG10*$AM$38 -> 54583.729 | AB10: =AH10*$AM$38 -> 36389.153 | AC10: =AI10*$AM$38*AC24 -> 30596.816 | AD10: =AJ10*$AM$38 -> 18358.09 | AE10: =AC10 -> 30596.816 | AF10: Obra | AG10: =AH10*$AG$1 -> 83.974968 | AH10: ='PAPEL US$'!I8 -> 55.983312 | AI10: ='PAPEL US$'!J6 -> 47.072025 | AJ10: =AI10*$AJ$1 -> 28.243215
B11: 1000 | C11: =(AC55+AC11)*AH$55 -> 167206.37 | D11: =(AC55*AG55+AC11)*AH55 -> 167397.47 | E11: =(AC55+AC4)*AH$55 -> 166855.67 | F11: =(AC55*AG55+AC4)*AH55 -> 167046.77 | G11: =(AC55+AC5)*$AH$55 -> 143058.14 | H11: =(AC55*AG55+AC5)*AH55 -> 143249.24 | I11: =(AC55+AC6)*$AH$55 -> 104982.1 | J11: =(AC55*AG55+AC6)*AH55 -> 105173.2 | K11: =(AC55+AC7)*$AH$55 -> 71665.571 | L11: =(AC55*AG55+AC7)*AH55 -> 71856.671 | M11: =(AC55+AC8)*$AH$55 -> 55007.305 | N11: =(AC55*AG55+AC8)*AH55 -> 55198.405 | O11: =(AC55+AC9)*AH$55 -> 43108.543 | P11: =(AC55*AG55+AC9)*AH55 -> 43299.643 | Q11: =(AC55+AC10)*AH$55 -> 43108.543 | R11: =(AC55*AG55+AC10)*AH55 -> 43299.643 | S11: =(AC55+$AC$12*AF55)*$AH$55 -> 385658 | T11: =(AC55+$AC$14)*AH55+AC5 -> 103653.65 | U11: =(AC55+$AC$13*AF55)*AH55 -> 988.715 | W11: 291 | X11: 371 | Z11: Triplex | AA11: =AG11*$AM$38 -> 178857.18 | AB11: =AH11*$AM$38 -> 119238.12 | AC11: =AI11*$AM$38*AC25 -> 119238.12 | AD11: =AJ11*$AM$38 -> 71542.871 | AE11: =AC11 -> 119238.12 | AF11: Triplex | AG11: =AH11*$AG$1 -> 275.16489 | AH11: ='PAPEL US$'!I29 -> 183.44326 | AI11: ='PAPEL US$'!J29 -> 183.44326 | AJ11: =AI11*$AJ$1 -> 110.06596
B12: XA3 (33x48) | C12: Triplex | E12: 350g | G12: 300g | I12: 200g | K12: 150g | M12: 115g | O12: 90g | Q12: OBRA | S12: Sticker | Z12: Sticker | AA12: =AG12*$AM$38 -> 495495 | AB12: =AH12*$AM$38 -> 330330 | AC12: =AI12*$AM$38*AC26 -> 275275 | AD12: =AJ12*$AM$38 -> 165165 | AE12: =AC12 -> 275275 | AF12: Sticker | AG12: =AH12*$AG$1 -> 762.3 | AH12: ='PAPEL US$'!L33 -> 508.2 | AI12: ='PAPEL US$'!J31 -> 423.5 | AJ12: =AI12*$AJ$1 -> 254.1
B13: 31x47 | C13: 4/0 | D13: 4/4 | E13: 4/0 | F13: 4/4 | G13: 4/0 | H13: 4/4 | I13: 4/0 | J13: 4/4 | K13: 4/0 | L13: 4/4 | M13: 4/0 | N13: 4/4 | O13: 4/0 | P13: 4/4 | Q13: 4/0 | R13: 4/4 | S13: 4/0 | Z13: OPP | AA13: =AG13*$AM$38 -> 0 | AB13: =AH13*$AM$38 -> 511.225 | AC13: =AI13*$AM$38*AC27 -> 511.225 | AD13: =AJ13*$AM$38 -> 0 | AE13: =AC13 -> 511.225 | AF13: OPP | AH13: ='PAPEL US$'!I36 -> 0.7865 | AI13: ='PAPEL US$'!J36 -> 0.7865
B14: 1 | C14: =(AB48+AB11)*$AH$48 -> 226922.93 | D14: =(AB48*AG48+AB11)*AH48 -> 227182.28 | E14: =(AB48+AB4)*$AH$48 -> 269245.91 | F14: =(AB48*AG48+AB4)*AH48 -> 269505.26 | G14: =(AB48+AB5)*$AH$48 -> 230835.13 | H14: =(AB48*AG48+AB5)*AH48 -> 231094.48 | I14: =(AB48+AB6)*$AH$48 -> 169377.9 | J14: =(AB48*AG48+AB6)*AH48 -> 169637.25 | K14: =(AB48+AB7)*$AH$48 -> 115602.82 | L14: =(AB48*AG48+AB7)*AH48 -> 115862.17 | M14: =(AB48+AB8)*$AH$48 -> 88715.277 | N14: =(AB48*AG48+AB8)*AH48 -> 88974.627 | O14: =(AB48+AB9)*$AH$48 -> 69509.89 | P14: =(AB48*AG48+AB9)*AH48 -> 69769.24 | Q14: =(AB48+AB10)*$AH$48 -> 69509.89 | R14: =(AB48*AG48+AB10)*AH48 -> 69769.24 | S14: =(AB48+AB12)*$AH$48 -> 627997.5 | W14: 533 | X14: 660 | Z14: Imán | AA14: =AG14*$AM$38 -> 0 | AB14: =AH14*$AM$38 -> #VALUE! | AC14: ='PAPEL US$'!H48 -> 993.76 | AF14: Imán | AH14: =AM41*AH26 -> #VALUE! | AI14: =AI5+'PAPEL US$'!J49 -> 1288.6534 | AJ14: 0
B15: 2 a 25 | C15: =(AB49+AB11)*$AH$49 -> 203036.3 | D15: =(AB49*AG49+AB11)*AH49 -> 203268.35 | E15: =(AB49+AB4)*$AH$49 -> 240904.23 | F15: =(AB49*AG49+AB4)*AH49 -> 241136.28 | G15: =(AB49+AB5)*$AH$49 -> 206536.7 | H15: =(AB49*AG49+AB5)*AH49 -> 206768.75 | I15: =(AB49+AB6)*$AH$49 -> 151548.65 | J15: =(AB49*AG49+AB6)*AH49 -> 151780.7 | K15: =(AB49+AB7)*$AH$49 -> 103434.1 | L15: =(AB49*AG49+AB8)*AH49 -> 79608.876 | M15: =(AB49+AB8)*$AH$49 -> 79376.826 | N15: =(AB49*AG49+AB8)*AH49 -> 79608.876 | O15: =(AB49+AB9)*$AH$49 -> 62193.06 | P15: =(AB49*AG49+AB9)*AH49 -> 62425.11 | Q15: =(AB49+AB10)*$AH$49 -> 62193.06 | R15: =(AB49*AG49+AD10)*AH49 -> 31772.303 | S15: =(AB49+AB12)*$AH$49 -> 561892.5 | W15: 504 | X15: 625
B16: 26 a 50 | C16: =(AB50+AB11)*$AH$50 -> 197064.65 | D16: =(AB50*AG50+AB12)*AH50 -> 545591.47 | E16: =(AB50+AB4)*$AH$50 -> 233818.81 | F16: =(AB50*AG50+AB4)*AH50 -> 234044.04 | G16: =(AB50+AB5)*$AH$50 -> 200462.09 | H16: =(AB50*AG50+AB5)*AH50 -> 200687.32 | I16: =(AB50+AB6)*$AH$50 -> 147091.33 | J16: =(AB50*AG50+AB6)*AH50 -> 147316.56 | K16: =(AB50+AB7)*$AH$50 -> 100391.92 | L16: =(AB50*AG50+AB8)*AH50 -> 77267.439 | M16: =(AB50+AB8)*$AH$50 -> 77042.214 | N16: =(AB50*AG50+AB8)*AH50 -> 77267.439 | O16: =(AB50+AB9)*$AH$50 -> 60363.852 | P16: =(AB50*AG50+AB9)*AH50 -> 60589.077 | Q16: =(AB50+AB10)*$AH$50 -> 60363.852 | R16: =(AB50*AG50+AD10)*AH50 -> 30837.823 | S16: =(AB50+AB12)*$AH$50 -> 545366.25 | W16: 476 | X16: 590 | Z16: Coeficiente papel | AB16: Parametros ajustables
B17: 51 a 100 | C17: =(AB51+AB11)*$AH$51 -> 191092.99 | D17: =(AB51*AG51+AB11)*AH51 -> 191311.39 | E17: =(AB51+AB4)*$AH$51 -> 226733.4 | F17: =(AB51*AG51+AB4)*AH51 -> 226951.8 | G17: =(AB51+AB5)*$AH$51 -> 194387.48 | H17: =(AB51*AG51+AB5)*AH51 -> 194605.88 | I17: =(AB51+AB6)*$AH$51 -> 142634.02 | J17: =(AB51*AG51+AB6)*AH51 -> 142852.42 | K17: =(AB51+AB7)*$AH$51 -> 97349.741 | L17: =(AB51*AG51+AB8)*AH51 -> 74926.001 | M17: =(AB51+AB8)*$AH$51 -> 74707.601 | N17: =(AB51*AG51+AB8)*AH51 -> 74926.001 | O17: =(AB51+AB9)*$AH$51 -> 58534.644 | P17: =(AB51*AG51+AB9)*AH51 -> 58753.044 | Q17: =(AB51+AB10)*$AH$51 -> 58534.644 | R17: =(AB51*AG51+AD10)*AH51 -> 29903.344 | S17: =(AB51+AB12)*$AH$51 -> 528840 | W17: 448 | X17: 555 | AA17: XL | AB17: 33X48 | AC17: 32X47 | AD17: A4 | AF17: COSTO DE BAJADA | AG17: (costo de papel x coef ganacia) + (costo clic * coef 4/0) + (costo clic x coef 4/4)
B18: 101 a 300 | C18: =(AB52+AB11)*$AH$52 -> 185121.33 | D18: =(AB52*AG52+AB11)*AH52 -> 185332.91 | E18: =(AB52+AB4)*$AH$52 -> 219647.98 | F18: =(AB52*AG52+AB4)*AH52 -> 219859.55 | G18: =(AC52+AB5)*$AH$52 -> 188312.87 | H18: =(AB52*AG52+AB5)*AH52 -> 188524.45 | I18: =(AB52+AB6)*$AH$52 -> 138176.71 | J18: =(AB52*AG52+AB6)*AH52 -> 138388.28 | K18: =(AB52+AB7)*$AH$52 -> 94307.561 | L18: =(AB52*AG52+AB8)*AH52 -> 72584.564 | M18: =(AB52+AB8)*$AH$52 -> 72372.989 | N18: =(AB52*AG52+AB8)*AH52 -> 72584.564 | O18: =(AB52+AB9)*$AH$52 -> 56705.437 | P18: =(AB52*AG52+AB9)*AH52 -> 56917.012 | Q18: =(AB52+AB10)*$AH$52 -> 56705.437 | R18: =(AB52*AG52+AD10)*AH52 -> 28968.864 | S18: =(AB52+AB12)*$AH$52 -> 512313.75 | W18: 436 | X18: 536 | Z18: 350g | AA18: 1 | AB18: 1 | AC18: 1 | AD18: 1 | AF18: COSTO DE PAPEL | AG18: costo de pliego/coef de corte
B19: 301 a 500 | C19: =(AB53+AB11)*$AH$53 -> 179149.68 | D19: =(AB53*AG53+AB11)*AH53 -> 179354.43 | E19: =(AB53+AB4)*$AH$53 -> 212562.56 | F19: =(AB53*AG53+AB4)*AH53 -> 212767.31 | G19: =(AC53+AB5)*$AH$53 -> 182238.26 | H19: =(AB53*AG53+AB5)*AH53 -> 182443.01 | I19: =(AB53+AB6)*$AH$53 -> 133719.39 | J19: =(AB53*AG53+AB6)*AH53 -> 133924.14 | K19: =(AB53+AB7)*$AH$53 -> 91265.382 | L19: =(AB53*AG53+AB8)*AH53 -> 70243.126 | M19: =(AB53+AB8)*$AH$53 -> 70038.376 | N19: =(AB53*AG53+AB8)*AH53 -> 70243.126 | O19: =(AB53+AB9)*$AH$53 -> 54876.229 | P19: =(AB53*AG53+AB9)*AH53 -> 55080.979 | Q19: =(AB53+AB10)*$AH$53 -> 54876.229 | R19: =(AB53*AG53+AD10)*AH53 -> 28034.385 | S19: =(AB53+AB12)*$AH$53 -> 495787.5 | W19: 392 | X19: 486 | Z19: 300g | AA19: 1 | AB19: 1 | AC19: 1 | AD19: 1 | AF19: costo de clic | AG19: toner + gastos amortiz
B20: 501 a 1000 | C20: =(AB54+AB11)*$AH$54 -> 173178.02 | D20: =(AB54*AG54+AB11)*AH54 -> 173375.95 | E20: =(AB54+AB4)*$AH$54 -> 205477.14 | F20: =(AB54*AG54+AB4)*AH54 -> 205675.06 | G20: =(AC54+AB5)*$AH$54 -> 176163.66 | H20: =(AB54*AG54+AB5)*AH54 -> 176361.58 | I20: =(AB54+AB6)*$AH$54 -> 129262.08 | J20: =(AB54*AG54+AB6)*AH54 -> 129460.01 | K20: =(AB54+AB7)*$AH$54 -> 88223.203 | L20: =(AB54*AG54+AB8)*AH54 -> 67901.689 | M20: =(AB54+AB8)*$AH$54 -> 67703.764 | N20: =(AB54*AG54+AB8)*AH54 -> 67901.689 | O20: =(AB54+AB9)*$AH$54 -> 53047.022 | P20: =(AB54*AG54+AB9)*AH54 -> 53244.947 | Q20: =(AB54+AB10)*$AH$54 -> 53047.022 | R20: =(AB54*AG54+AD10)*AH54 -> 27099.905 | S20: =(AB54+AB12)*$AH$54 -> 479261.25 | W20: 363 | X20: 451 | Z20: 200g | AA20: 1 | AB20: 1 | AC20: 1 | AD20: 1
B21: 1000 | C21: =(AB55+AB11)*$AH$55 -> 167206.37 | D21: =(AB55*AG55+AB11)*AH55 -> 167397.47 | E21: =(AB55+AB4)*$AH$55 -> 198391.72 | F21: =(AB55*AG55+AB4)*AH55 -> 198582.82 | G21: =(AC55+AB5)*$AH$55 -> 170089.05 | H21: =(AB55*AG55+AB12)*AH55 -> 462926.1 | I21: =(AB55+AB6)*$AH$55 -> 124804.77 | J21: =(AB55*AG55+AB6)*AH55 -> 124995.87 | K21: =(AB55+AB7)*$AH$55 -> 85181.023 | L21: =(AB55*AG55+AB8)*AH55 -> 65560.251 | M21: =(AB55+AB8)*$AH$55 -> 65369.151 | N21: =(AB55*AG55+AB8)*AH55 -> 65560.251 | O21: =(AB55+AB9)*$AH$55 -> 51217.814 | P21: =(AB55*AG55+AB9)*AH55 -> 51408.914 | Q21: =(AB55+AB10)*$AH$55 -> 51217.814 | R21: =(AB55*AG55+AD10)*AH55 -> 26165.426 | S21: =(AB55+AB12)*$AH$55 -> 462735 | Z21: 150g | AA21: 1 | AB21: 1 | AC21: 1 | AD21: 1 | AG21: costo de bobina iman
B22: XL 32x70 | C22: Triplex | E22: 350g | G22: 300g | I22: 200g | K22: 150g | M22: 115g | O22: 90g | Q22: OBRA | S22: Sticker | W22: =W14-W4 -> 73 | X22: =X14-X4 -> 72 | Z22: 115g | AA22: 1 | AB22: 1 | AC22: 1 | AD22: 1 | AH22: 21 | AI22: IMAN A3+ | AJ22: 1.5
